Workbook

Sheet INDEX 
A1: NO | B1: DÈSIGNATION | C1: RESTE QTY / PCS | D1: RESTE QTY / CTN | E1: BALANCE / CNT
A2: 1 | B2: COCO PAA PRINCESS CRÈME 460G | C2: ='COCO PAA PRINCESS CRÈME 460G'!E13 -> 12384 | D2: =C2/48 -> 258 | E2: =D2+D3+D4+D5+D6+D7+D8+D9+D10 -> 1097
A3: =+A2+1 -> 2 | B3: COCO PAA PRINCESS CRÈME 260G | C3: ='COCO PAA PRINCESS CRÈME 260G'!E15 -> 3600 | D3: =C3/72 -> 50
A4: =A3+1 -> 3 | B4: COCO PAA PRINCESS CRÈME 150G | C4: ='COCO PAA PRINCESS CRÈME 150G'!E11 -> 6408 | D4: =C4/72 -> 89
A5: =A4+1 -> 4 | B5: BO-16 HAIR FOOD BLEU 225ML | C5: ='BO-16 HAIR FOOD BLEU 225ML'!E14 -> 6480 | D5: =C5/48 -> 135
A6: =A5+1 -> 5 | B6: BO-16 HAIR FOOD JAUNE 225ML | C6: ='BO-16 HAIR FOOD JAUNE 225ML'!E11 -> 8832 | D6: =C6/48 -> 184
A7: =A6+1 -> 6 | B7: PARFUME INTENSE 100ML | C7: ='PARFUME INTENSE 100ML'!E15 -> 7536 | D7: =C7/48 -> 157
A8: =A7+1 -> 7 | B8: PARFUME LEGEND 100ML | C8: ='PARFUME LEGEND 100ML'!E16 -> 3600 | D8: =C8/48 -> 75
A9: =A8+1 -> 8 | B9: 'PARFUME BLOSSOM 100ML '!A1 | C9: ='PARFUME BLOSSOM 100ML'!E20 -> 3600 | D9: =C9/48 -> 75
A10: =A9+1 -> 9 | B10: PARFUME OUD 100ML | C10: ='PARFUME OUD 100ML'!E25 -> 3552 | D10: =C10/48 -> 74
A11: =A10+1 -> 10 | B11: PRINCESS CREAM C.B M/S 260ML | C11: ='PRINCESS CREAM C.B M S 260ML '!E22 -> 0 | D11: =C11/72 -> 0
A12: =A11+1 -> 11 | B12: PRINCESS CREAM C.B S/S 150ML | C12: ='PRINCESS CREAM C.B S S 150ML '!E34 -> 0 | D12: =C12/72 -> 0
A13: =A12+1 -> 12 | B13: CARRO PAA PRINCESS B/S 460ML | C13: =' CARRO PAA PRINCESS B S 460ML '!E27 -> 0 | D13: =C13/48 -> 0
A14: =A13+1 -> 13 | B14: CARRO PAA PRINCESS M/S 260ML | C14: =' CARRO PAA PRINCESS M S 260ML '!E13 -> 0 | D14: =C14/72 -> 0
A15: =A14+1 -> 14 | B15: CARRO PAA PRINCESS S/S 150ML | C15: ='CARRO PAA PRINCESS S S 150ML '!E14 -> 0 | D15: =C15/72 -> 0
A16: =A15+1 -> 15 | B16: 'CARRO PAA LOTION B S 400ML '!A1 | C16: ='CARRO PAA LOTION B S 400ML '!E8 -> 0 | D16: =C16/48 -> 0
A17: =A16+1 -> 16 | B17: CARRO PAA LOTION S/S 260ML | C17: ='CARRO PAA LOTION S S 260ML '!E11 -> 0 | D17: =C17/60 -> 0
A18: =A17+1 -> 17 | B18: KLEANZ HAND SANITIZER 100 ML | C18: ='KLEANZ HAND SANITIZER 100 ML '!E8 -> 0 | D18: =C18/60 -> 0
A19: =A18+1 -> 18 | B19: KLEANZ HAND SANITIZER 50 ML | C19: ='KLEANZ HAND SANITIZER 50 ML'!E15 -> 0 | D19: =C19/60 -> 0
A20: =A19+1 -> 19 | B20: 'HABIBA PDE B S 250 ML'!A1 | C20: ='HABIBA PDE B S 250 ML'!E10 -> 0 | D20: =C20/60 -> 0
A21: =A20+1 -> 20 | B21: 'HABIBA PDE S S 150 ML'!A1 | C21: ='HABIBA PDE S S 150 ML'!E7 -> 0 | D21: =C21/60 -> 0
A22: =A21+1 -> 21 | B22: 'HABIBA SHEA BUTTER PDE B S 250'!A1 | C22: ='HABIBA SHEA BUTTER PDE B S 250'!E13 -> 0 | D22: =C22/60 -> 0
A23: =A22+1 -> 22 | B23: 'STYLE UP 3 IN 1 SHOWER GEL ICE '!A1 | C23: ='STYLE UP 3 IN 1 SHOWER GEL ICE '!E17 -> 0 | D23: =C23/60 -> 0
A24: =A23+1 -> 23 | B24: 'STYLE UP 3 IN1 SHOWER GEL FRESH'!A1 | C24: ='STYLE UP 3 IN1 SHOWER GEL FRESH'!E12 -> 0 | D24: =C24/60 -> 0
A25: =A24+1 -> 24 | B25: 'STYLE UP 3 IN1 SHOWER GEL SPORT'!A1 | C25: ='STYLE UP 3 IN1 SHOWER GEL SPORT'!E13 -> 0 | D25: =C25/60 -> 0
A26: =A25+1 -> 25 | B26: 'STYLE UP SHOWER GEL FOCUS 1050'!A1 | C26: ='STYLE UP SHOWER GEL FOCUS 1050'!E30 -> 0 | D26: =C26/60 -> 0
A27: =A26+1 -> 26 | B27: 'STYLE UP SHOWER GEL SPORT 1050'!A1 | C27: ='STYLE UP SHOWER GEL SPORT 1050'!E15 -> 0 | D27: =C27/60 -> 0
A28: =A27+1 -> 27 | B28: 'STYLEUP SHOWER GEL STAMINA 1050'!A1 | C28: ='STYLEUP SHOWER GEL STAMINA 1050'!E15 -> 0 | D28: =C28/60 -> 0
A29: =A28+1 -> 28 | B29: 'STYLE UP SHOWER GEL POWER 1050'!A1 | C29: ='STYLE UP SHOWER GEL POWER 1050'!E14 -> 0 | D29: =C29/60 -> 0
A30: =A29+1 -> 29 | B30: 'STYLE UP SHOWER GEL RELAX 1050 | C30: ='STYLE UP SHOWER GEL RELAX 1050'!E14 -> 0 | D30: =C30/60 -> 0
A31: =A30+1 -> 30 | B31: 'BO-16 HERBAL CARE 280GR '!A1 | C31: ='BO-16 HERBAL CARE 280GR '!E11 -> 0 | D31: =C31/60 -> 0
A32: =A31+1 -> 31 | B32: 'BO-16 HAIR FOOD VITAMINS 225ML'!A1 | C32: ='BO-16 HAIR FOOD VITAMINS 225ML'!E14 -> 0 | D32: =C32/60 -> 0
A33: =A32+1 -> 32 | B33: 'BO-16 HAIR FOOD 225ML '!A1 | C33: ='BO-16 HAIR FOOD 225ML '!E12 -> 0 | D33: =C33/60 -> 0
A34: =A33+1 -> 33 | B34: 'KLEANZ BODY WASH ALOE VERA 750'!A1 | C34: ='KLEANZ BODY WASH ALOE VERA 750'!E17 -> 0 | D34: =C34/60 -> 0
A35: =A34+1 -> 34 | B35: 'KLEANZ BODY WASH STRAWBER 750ML'!A1 | C35: ='KLEANZ BODY WASH STRAWBER 750ML'!E9 -> 0 | D35: =C35/60 -> 0
A36: =A35+1 -> 35 | B36: 'KLEANZ BODYWASH ANTIBACTIRAL750'!A1 | C36: ='KLEANZ BODYWASH ANTIBACTIRAL750'!E13 -> 0 | D36: =C36/60 -> 0
A37: =A36+1 -> 36 | B37: 'KLEANZ BODY WASH VANILLA 750'!A1 | C37: ='KLEANZ BODY WASH VANILLA 750'!E11 -> 0 | D37: =C37/60 -> 0
A38: =A37+1 -> 37 | B38: 'KLEANZ BODY COCONUT OIL 750ML'!A1 | C38: ='KLEANZ BODY COCONUT OIL 750ML'!E15 -> 0 | D38: =C38/60 -> 0
A39: =A38+1 -> 38 | B39: 'CLASSIC HAIR PDE S-S 125 ML '!A1 | C39: ='CLASSIC HAIR PDE S-S 125 ML '!E9 -> 0 | D39: =C39/60 -> 0
A40: =A39+1 -> 39 | B40: 'CLASSIC HAIR PDE B-S 300 ML '!A1 | C40: ='CLASSIC HAIR PDE B-S 300 ML '!E19 -> 0 | D40: =C40/60 -> 0
...

Sheet COCO PAA PRINCESS CRÈME 460G
A1: COCO PAA PRINCESS CRÈME 460G
A3: DATE | B3: DÉSIGNATION | C3: RENTRÉ / PCS | D3: SORIE / PCS | E3: RESTE / PCS | F3: BALANCE / CNT
A4: 46241 | E4: 15792 | F4: 48
A5: 46610 | B5: ALHASSANE KINDIA | D5: 2400 | E5: =E4-D5+C5 -> 13392 | F5: =E5/F4 -> 279
B6: AMADOU OURY | D6: 48 | E6: =E5-D6+C6 -> 13344 | F6: =E6/F4 -> 278
B7: EL.OUSMSNE TANOU | D7: 240 | E7: =E6-D7+C7 -> 13104 | F7: =E7/F4 -> 273
B8: SALIOU | D8: 192 | E8: =E7-D8+C8 -> 12912 | F8: =E8/F4 -> 269
B9: EL.ALSENY | D9: 48 | E9: =E8-D9+C9 -> 12864 | F9: =E9/F4 -> 268
B10: ISMAİËL | D10: 96 | E10: =E9-D10+C10 -> 12768 | F10: =E10/F4 -> 266
B11: LALIT | D11: 240 | E11: =E10-D11+C11 -> 12528 | F11: =E11/F4 -> 261
A12: 46246 | B12: BOUBACAR BORDEAU | D12: 96 | E12: =E11-D12+C12 -> 12432 | F12: =E12/F4 -> 259
B13: KARIM | D13: 48 | E13: =E12-D13+C13 -> 12384 | F13: =E13/F4 -> 258
B14: SIDDI BAH | D14: 48 | E14: =E13-D14+C14 -> 12336 | F14: =E14/F4 -> 257
B15: MOUNTAGA | D15: 48 | E15: =E14-D15+C15 -> 12288 | F15: =E15/F4 -> 256
B16: AMADOU BIRO | D16: 48 | E16: =E15-D16+C16 -> 12240 | F16: =E16/F4 -> 255
B17: LALIT MAHENDER POUR KANKAN | D17: 2880 | E17: =E16-D17+C17 -> 9360 | F17: =E17/F4 -> 195
E18: =E17-D18+C18 -> 9360 | F18: =E18/F4 -> 195
E19: =E18-D19+C19 -> 9360 | F19: =E19/F4 -> 195
E20: =E19-D20+C20 -> 9360 | F20: =E20/F4 -> 195
E21: =E20-D21+C21 -> 9360 | F21: =E21/F4 -> 195
E22: =E21-D22+C22 -> 9360 | F22: =E22/F4 -> 195
E23: =E22-D23+C23 -> 9360 | F23: =E23/F4 -> 195
E24: =E23-D24+C24 -> 9360 | F24: =E24/F4 -> 195
E25: =E24-D25+C25 -> 9360 | F25: =E25/F4 -> 195
E26: =E25-D26+C26 -> 9360 | F26: =E26/F4 -> 195
E27: =E26-D27+C27 -> 9360 | F27: =E27/F4 -> 195
E28: =E27-D28+C28 -> 9360 | F28: =E28/F4 -> 195
E29: =E28-D29+C29 -> 9360 | F29: =E29/F4 -> 195
E30: =E29-D30+C30 -> 9360 | F30: =E30/F4 -> 195
E31: =E30-D31+C31 -> 9360 | F31: =E27/F4 -> 195
E32: =E31-D32+C32 -> 9360 | F32: =E32/F4 -> 195
E33: =E32-D33+C33 -> 9360 | F33: =E33/F4 -> 195
E34: =E33-D34+C34 -> 9360 | F34: =E34/F4 -> 195
E35: =E34-D35+C35 -> 9360 | F35: =E35/F4 -> 195
E36: =E35-D36+C36 -> 9360 | F36: =E36/F4 -> 195
E37: =E36-D37+C37 -> 9360 | F37: =E37/F4 -> 195
E38: =E37-D38+C38 -> 9360 | F38: =E38/F4 -> 195
E39: =E38-D39+C39 -> 9360 | F39: =E39/F4 -> 195
E40: =E39-D40+C40 -> 9360 | F40: =E40/F4 -> 195
E41: =E40-D41+C41 -> 9360 | F41: =E41/F4 -> 195
...

Sheet COCO PAA PRINCESS CRÈME 260G
A1: COCO PAA PRINCESS CRÈME 260G
A3: DATE | B3: DÉSIGNATION | C3: RENTRÉ / PCS | D3: SORIE / PCS | E3: RESTE / PCS | F3: BALANCE / CNT
A4: 46241 | E4: 11160 | F4: 72
A5: 46241 | B5: LALIT | D5: 360 | E5: =E4-D5+C5 -> 10800 | F5: =E5/F4 -> 150
A6: 46245 | B6: LALIT MAHENDER POUR KANKAN | D6: 4032 | E6: =E5-D6+C6 -> 6768 | F6: =E6/F4 -> 94
B7: ALHASSANE KINDIA | D7: 2160 | E7: =E6-D7+C7 -> 4608 | F7: =E7/F4 -> 64
B8: EL.OUSMSNE TANOU | D8: 360 | E8: =E7-D8+C8 -> 4248 | F8: =E8/F4 -> 59
B9: SALIOU | D9: 144 | E9: =E8-D9+C9 -> 4104 | F9: =E9/F4 -> 57
B10: EL.ALSENY | D10: 72 | E10: =E9-D10+C10 -> 4032 | F10: =E10/F4 -> 56
B11: ISMAİËL | D11: 144 | E11: =E10-D11+C11 -> 3888 | F11: =E11/F4 -> 54
A12: 46246 | B12: BOUBACAR BORDEAU | D12: 144 | E12: =E11-D12+C12 -> 3744 | F12: =E12/F4 -> 52
B13: KARIM | D13: 72 | E13: =E12-D13+C13 -> 3672 | F13: =E13/F4 -> 51
B14: SIDDI BAH | D14: 72 | E14: =E13-D14+C14 -> 3600 | F14: =E14/F4 -> 50
E15: =E14-D15+C15 -> 3600 | F15: =E15/F4 -> 50
E16: =E15-D16+C16 -> 3600 | F16: =E16/F4 -> 50
E17: =E16-D17+C17 -> 3600 | F17: =E17/F4 -> 50
E18: =E17-D18+C18 -> 3600 | F18: =E18/F4 -> 50
E19: =E18-D19+C19 -> 3600 | F19: =E19/F4 -> 50
E20: =E19-D20+C20 -> 3600 | F20: =E20/F4 -> 50
E21: =E20-D21+C21 -> 3600 | F21: =E21/F4 -> 50
E22: =E21-D22+C22 -> 3600 | F22: =E22/F4 -> 50
E23: =E22-D23+C23 -> 3600 | F23: =E23/F4 -> 50
E24: =E23-D24+C24 -> 3600 | F24: =E24/F4 -> 50
E25: =E24-D25+C25 -> 3600 | F25: =E25/F4 -> 50
E26: =E25-D26+C26 -> 3600 | F26: =E26/F4 -> 50
E27: =E26-D27+C27 -> 3600 | F27: =E26/F4 -> 50
E28: =E27-D28+C28 -> 3600 | F28: =E28/F4 -> 50
E29: =E28-D29+C29 -> 3600 | F29: =E29/F4 -> 50
E30: =E29-D30+C30 -> 3600 | F30: =E30/F4 -> 50
E31: =E30-D31+C31 -> 3600 | F31: =E31/F4 -> 50
E32: =E31-D32+C32 -> 3600 | F32: =E32/F4 -> 50
E33: =E32-D33+C33 -> 3600 | F33: =E33/F4 -> 50
E34: =E33-D34+C34 -> 3600 | F34: =E34/F4 -> 50
E35: =E34-D35+C35 -> 3600 | F35: =E35/F4 -> 50
E36: =E35-D36+C36 -> 3600 | F36: =E36/F4 -> 50
E37: =E36-D37+C37 -> 3600 | F37: =E37/F4 -> 50
E38: =E37-D38+C38 -> 3600 | F38: =E38/F4 -> 50
E39: =E38-D39+C39 -> 3600 | F39: =E39/F4 -> 50
E40: =E39-D40+C40 -> 3600 | F40: =E40/F4 -> 50
E41: =E40-D41+C41 -> 3600 | F41: =E41/F4 -> 50
...

Sheet COCO PAA PRINCESS CRÈME 150G
A1: COCO PAA PRINCESS CRÈME 150G
A3: DATE | B3: DÉSIGNATION | C3: RENTRÉ | D3: SOTIE | E3: BALANCE | F3: BALANCE / CNT
A4: 46241 | E4: 9792 | F4: 72
A5: 46245 | B5: LALIT | D5: 360 | E5: =E4-D5+C5 -> 9432 | F5: =E5/F4 -> 131
B6: ALHASSANE KINDIA | D6: 2160 | E6: =E5-D6+C6 -> 7272 | F6: =E6/F4 -> 101
B7: EL.OUSMSNE TANOU | D7: 360 | E7: =E6-D7+C7 -> 6912 | F7: =E7/F4 -> 96
B8: SALIOU | D8: 144 | E8: =E7-D8+C8 -> 6768 | F8: =E8/F4 -> 94
B9: EL.ALSENY | D9: 72 | E9: =E8-D9+C9 -> 6696 | F9: =E9/F4 -> 93
B10: ISMAİËL | D10: 144 | E10: =E9-D10+C10 -> 6552 | F10: =E10/F4 -> 91
A11: 46246 | B11: BOUBACAR BORDEAU | D11: 144 | E11: =E10-D11+C11 -> 6408 | F11: =E11/F4 -> 89
B12: KARIM | D12: 72 | E12: =E11-D12+C12 -> 6336 | F12: =E12/F4 -> 88
B13: SIDDI BAH | D13: 72 | E13: =E12-D13+C13 -> 6264 | F13: =E13/F4 -> 87
B14: LALIT MAHENDER POUR KANKAN | D14: 3600 | E14: =E13-D14+C14 -> 2664 | F14: =E14/F4 -> 37
E15: =E14-D15+C15 -> 2664 | F15: =E15/F4 -> 37
E16: =E15-D16+C16 -> 2664 | F16: =E16/F4 -> 37
E17: =E16-D17+C17 -> 2664 | F17: =E17/F4 -> 37
E18: =E17-D18+C18 -> 2664 | F18: =E18/F4 -> 37
E19: =E18-D19+C19 -> 2664 | F19: =E19/F4 -> 37
E20: =E19-D20+C20 -> 2664 | F20: =E20/F4 -> 37
E21: =E20-D21+C21 -> 2664 | F21: =E21/F4 -> 37
E22: =E21-D22+C22 -> 2664 | F22: =E22/F4 -> 37
E23: =E22-D23+C23 -> 2664 | F23: =E23/F4 -> 37
E24: =E23-D24+C24 -> 2664 | F24: =E24/F4 -> 37
E25: =E24-D25+C25 -> 2664 | F25: =E25/F4 -> 37
E26: =E25-D26+C26 -> 2664 | F26: =E26/F4 -> 37
E27: =E26-D27+C27 -> 2664 | F27: =E27/F4 -> 37
E28: =E27-D28+C28 -> 2664 | F28: =E28/F4 -> 37
E29: =E28-D29+C29 -> 2664 | F29: =E29/F4 -> 37
E30: =E29-D30+C30 -> 2664 | F30: =E30/F4 -> 37
E31: =E30-D31+C31 -> 2664 | F31: =E31/F4 -> 37
E32: =E31-D32+C32 -> 2664 | F32: =E32/F4 -> 37
E33: =E32-D33+C33 -> 2664 | F33: =E33/F4 -> 37
E34: =E33-D34+C34 -> 2664 | F34: =E34/F4 -> 37
E35: =E34-D35+C35 -> 2664 | F35: =E35/F4 -> 37
E36: =E35-D36+C36 -> 2664 | F36: =E36/F4 -> 37
E37: =E36-D37+C37 -> 2664 | F37: =E37/F4 -> 37
E38: =E37-D38+C38 -> 2664 | F38: =E38/F4 -> 37
E39: =E38-D39+C39 -> 2664 | F39: =E39/F4 -> 37
E40: =E39-D40+C40 -> 2664 | F40: =E40/F4 -> 37
E41: =E40-D41+C41 -> 2664 | F41: =E41/F4 -> 37
...

Sheet BO-16 HAIR FOOD BLEU 225ML
A1: BO-16 HAIR FOOD BLEU 225ML
A3: DATE | B3: DÉSIGNATION | C3: RENTRÉ | D3: SOTIE | E3: BALANCE | F3: BALANCE / CNT
A4: 46241 | E4: 10368 | F4: 48
A5: 46241 | B5: LALIT | D5: 2400 | E5: =E4-D5+C5 -> 7968 | F5: =E5/F4 -> 166
A6: 46245 | B6: ALHASSANE KINDIA | D6: 720 | E6: =E5-D6+C6 -> 7248 | F6: =E6/F4 -> 151
B7: EL.OUSMSNE TANOU | D7: 144 | E7: =E6-D7+C7 -> 7104 | F7: =E7/F4 -> 148
B8: SOULEMANE SOW | D8: 48 | E8: =E7-D8+C8 -> 7056 | F8: =E8/F4 -> 147
B9: SALIOU | D9: 240 | E9: =E8-D9+C9 -> 6816 | F9: =E9/F4 -> 142
B10: EL.ALSENY | D10: 48 | E10: =E9-D10+C10 -> 6768 | F10: =E10/F4 -> 141
B11: ISMAİËL | D11: 96 | E11: =E10-D11+C11 -> 6672 | F11: =E11/F4 -> 139
A12: 46246 | B12: BOUBACAR BORDEAU | D12: 96 | E12: =E11-D12+C12 -> 6576 | F12: =E12/F4 -> 137
B13: KARIM | D13: 48 | E13: =E12-D13+C13 -> 6528 | F13: =E13/F4 -> 136
B14: SIDDI BAH | D14: 48 | E14: =E13-D14+C14 -> 6480 | F14: =E14/F4 -> 135
B15: IBRAHIMA MORON | D15: 48 | E15: =E14-D15+C15 -> 6432 | F15: =E15/F4 -> 134
B16: MOUNTAGA | D16: 96 | E16: =E15-D16+C16 -> 6336 | F16: =E16/F4 -> 132
B17: AMADOU BIRO | D17: 96 | E17: =E16-D17+C17 -> 6240 | F17: =E17/F4 -> 130
B18: EL.SALL | D18: 48 | E18: =E17-D18+C18 -> 6192 | F18: =E18/F4 -> 129
B19: SIDDI | D19: 1440 | E19: =E18-D19+C19 -> 4752 | F19: =E19/F4 -> 99
E20: =E19-D20+C20 -> 4752 | F20: =E20/F4 -> 99
E21: =E20-D21+C21 -> 4752 | F21: =E21/F4 -> 99
E22: =E21-D22+C22 -> 4752 | F22: =E22/F4 -> 99
E23: =E22-D23+C23 -> 4752 | F23: =E23/F4 -> 99
E24: =E23-D24+C24 -> 4752 | F24: =E24/F4 -> 99
E25: =E24-D25+C25 -> 4752 | F25: =E25/F4 -> 99
E26: =E25-D26+C26 -> 4752 | F26: =E26/F4 -> 99
E27: =E26-D27+C27 -> 4752 | F27: =E27/F4 -> 99
E28: =E27-D28+C28 -> 4752 | F28: =E28/F4 -> 99
E29: =E28-D29+C29 -> 4752 | F29: =E29/F4 -> 99
E30: =E29-D30+C30 -> 4752 | F30: =E30/F4 -> 99
E31: =E30-D31+C31 -> 4752 | F31: =E31/F4 -> 99
E32: =E31-D32+C32 -> 4752 | F32: =E32/F4 -> 99
E33: =E32-D33+C33 -> 4752 | F33: =E33/F4 -> 99
E34: =E33-D34+C34 -> 4752 | F34: =E34/F4 -> 99
E35: =E34-D35+C35 -> 4752 | F35: =E35/F4 -> 99
E36: =E35-D36+C36 -> 4752 | F36: =E36/F4 -> 99
E37: =E36-D37+C37 -> 4752 | F37: =E37/F4 -> 99
E38: =E37-D38+C38 -> 4752 | F38: =E38/F4 -> 99
E39: =E38-D39+C39 -> 4752 | F39: =E39/F4 -> 99
E40: =E39-D40+C40 -> 4752 | F40: =E40/F4 -> 99
E41: =E40-D41+C41 -> 4752 | F41: =E41/F4 -> 99
...

Sheet BO-16 HAIR FOOD JAUNE 225ML
A1: BO-16 HAIR FOOD JAUNE 225ML
A3: DATE | B3: DÉSIGNATION | C3: RENTRÉ | D3: SOTIE | E3: BALANCE | F3: BALANCE / CNT
A4: 46241 | E4: 10320 | F4: 48
A5: 46241 | B5: LALIT | D5: 240 | E5: =E4-D5+C5 -> 10080 | F5: =E5/F4 -> 210
A6: 46245 | B6: ALHASSANE KINDIA | D6: 720 | E6: =E5-D6+C6 -> 9360 | F6: =E6/F4 -> 195
B7: EL.OUSMSNE TANOU | D7: 96 | E7: =E6-D7+C7 -> 9264 | F7: =E7/F4 -> 193
B8: SOULEMANE SOW | D8: 48 | E8: =E7-D8+C8 -> 9216 | F8: =E8/F4 -> 192
B9: SALIOU | D9: 240 | E9: =E8-D9+C9 -> 8976 | F9: =E9/F4 -> 187
B10: EL.ALSENY | D10: 48 | E10: =E9-D10+C10 -> 8928 | F10: =E10/F4 -> 186
B11: ISMAİËL | D11: 96 | E11: =E10-D11+C11 -> 8832 | F11: =E11/F4 -> 184
A12: 46246 | B12: BOUBACAR BORDEAU | D12: 96 | E12: =E11-D12+C12 -> 8736 | F12: =E12/F4 -> 182
B13: KARIM | D13: 48 | E13: =E12-D13+C13 -> 8688 | F13: =E13/F4 -> 181
B14: SIDDI BAH | D14: 48 | E14: =E13-D14+C14 -> 8640 | F14: =E14/F4 -> 180
B15: MOUNTAGA | D15: 48 | E15: =E14-D15+C15 -> 8592 | F15: =E15/F4 -> 179
B16: AMADOU BIRO | D16: 96 | E16: =E15-D16+C16 -> 8496 | F16: =E16/F4 -> 177
B17: SIDDI | D17: 1440 | E17: =E16-D17+C17 -> 7056 | F17: =E17/F4 -> 147
E18: =E17-D18+C18 -> 7056 | F18: =E18/F4 -> 147
E19: =E18-D19+C19 -> 7056 | F19: =E19/F4 -> 147
E20: =E19-D20+C20 -> 7056 | F20: =E20/F4 -> 147
E21: =E20-D21+C21 -> 7056 | F21: =E21/F4 -> 147
E22: =E21-D22+C22 -> 7056 | F22: =E22/F4 -> 147
E23: =E22-D23+C23 -> 7056 | F23: =E23/F4 -> 147
E24: =E23-D24+C24 -> 7056 | F24: =E24/F4 -> 147
E25: =E24-D25+C25 -> 7056 | F25: =E25/F4 -> 147
E26: =E25-D26+C26 -> 7056 | F26: =E26/F4 -> 147
E27: =E26-D27+C27 -> 7056 | F27: =E27/F4 -> 147
E28: =E27-D28+C28 -> 7056 | F28: =E28/F4 -> 147
E29: =E28-D29+C29 -> 7056 | F29: =E29/F4 -> 147
E30: =E29-D30+C30 -> 7056 | F30: =E30/F4 -> 147
E31: =E30-D31+C31 -> 7056 | F31: =E31/F4 -> 147
E32: =E31-D32+C32 -> 7056 | F32: =E32/F4 -> 147
E33: =E32-D33+C33 -> 7056 | F33: =E33/F4 -> 147
E34: =E33-D34+C34 -> 7056 | F34: =E34/F4 -> 147
E35: =E34-D35+C35 -> 7056 | F35: =E35/F4 -> 147
E36: =E35-D36+C36 -> 7056 | F36: =E36/F4 -> 147
E37: =E36-D37+C37 -> 7056 | F37: =E37/F4 -> 147
E38: =E37-D38+C38 -> 7056 | F38: =E38/F4 -> 147
E39: =E38-D39+C39 -> 7056 | F39: =E39/F4 -> 147
E40: =E39-D40+C40 -> 7056 | F40: =E40/F4 -> 147
E41: =E40-D41+C41 -> 7056 | F41: =E41/F4 -> 147
...

Sheet PARFUME INTENSE 100ML
A1: PARFUME INTENSE 100ML
A3: DATE | B3: DÉSIGNATION | C3: RENTRÉ | D3: SOTIE | E3: BALANCE | F3: BALANCE / CNT
A4: 46241 | E4: 7872 | F4: 48
A5: 46241 | B5: LALIT | D5: 240 | E5: =E4-D5+C5 -> 7632 | F5: =E5/F4 -> 159
A6: 46245 | B6: SALIOU | D6: 48 | E6: =E5-D6+C6 -> 7584 | F6: =E6/F4 -> 158
B7: ISMAİËL | D7: 48 | E7: =E6-D7+C7 -> 7536 | F7: =E7/F4 -> 157
E8: =E7-D8+C8 -> 7536 | F8: =E8/F4 -> 157
E9: =E8-D9+C9 -> 7536 | F9: =E9/F4 -> 157
E10: =E9-D10+C10 -> 7536 | F10: =E10/F4 -> 157
E11: =E10-D11+C11 -> 7536 | F11: =E11/F4 -> 157
E12: =E11-D12+C12 -> 7536 | F12: =E12/F4 -> 157
E13: =E12-D13+C13 -> 7536 | F13: =E13/F4 -> 157
E14: =E13-D14+C14 -> 7536 | F14: =E14/F4 -> 157
E15: =E14-D15+C15 -> 7536 | F15: =E15/F4 -> 157
E16: =E15-D16+C16 -> 7536 | F16: =E16/F4 -> 157
E17: =E16-D17+C17 -> 7536 | F17: =E17/F4 -> 157
E18: =E17-D18+C18 -> 7536 | F18: =E18/F4 -> 157
E19: =E18-D19+C19 -> 7536 | F19: =E19/F4 -> 157
E20: =E19-D20+C20 -> 7536 | F20: =E20/F4 -> 157
E21: =E20-D21+C21 -> 7536 | F21: =E21/F4 -> 157
E22: =E21-D22+C22 -> 7536 | F22: =E22/F4 -> 157
E23: =E22-D23+C23 -> 7536 | F23: =E23/F4 -> 157
E24: =E23-D24+C24 -> 7536 | F24: =E24/F4 -> 157
E25: =E24-D25+C25 -> 7536 | F25: =E25/F4 -> 157
E26: =E25-D26+C26 -> 7536 | F26: =E26/F4 -> 157
E27: =E26-D27+C27 -> 7536 | F27: =E27/F4 -> 157
E28: =E27-D28+C28 -> 7536 | F28: =E28/F4 -> 157
E29: =E28-D29+C29 -> 7536 | F29: =E29/F4 -> 157
E30: =E29-D30+C30 -> 7536 | F30: =E30/F4 -> 157
E31: =E30-D31+C31 -> 7536 | F31: =E31/F4 -> 157
E32: =E31-D32+C32 -> 7536 | F32: =E32/F4 -> 157
E33: =E32-D33+C33 -> 7536 | F33: =E33/F4 -> 157
E34: =E33-D34+C34 -> 7536 | F34: =E34/F4 -> 157
E35: =E34-D35+C35 -> 7536 | F35: =E35/F4 -> 157
E36: =E35-D36+C36 -> 7536 | F36: =E36/F4 -> 157
E37: =E36-D37+C37 -> 7536 | F37: =E37/F4 -> 157
E38: =E37-D38+C38 -> 7536 | F38: =E38/F4 -> 157
E39: =E38-D39+C39 -> 7536 | F39: =E39/F4 -> 157
E40: =E39-D40+C40 -> 7536 | F40: =E40/F4 -> 157
E41: =E40-D41+C41 -> 7536 | F41: =E41/F4 -> 157
...

Sheet PARFUME LEGEND 100ML
A1: PARFUME LEGEND 100ML
A3: DATE | B3: DÉSIGNATION | C3: RENTRÉ | D3: SOTIE | E3: BALANCE | F3: BALANCE / CNT
A4: 46241 | E4: 3936 | F4: 48
A5: 46241 | B5: LALIT | D5: 240 | E5: =E4-D5+C5 -> 3696 | F5: =E5/F4 -> 77
A6: 46245 | B6: SALIOU | D6: 48 | E6: =E5-D6+C6 -> 3648 | F6: =E6/F4 -> 76
B7: ISMAİËL | D7: 48 | E7: =E6-D7+C7 -> 3600 | F7: =E7/F4 -> 75
E8: =E7-D8+C8 -> 3600 | F8: =E8/F4 -> 75
E9: =E8-D9+C9 -> 3600 | F9: =E9/F4 -> 75
E10: =E9-D10+C10 -> 3600 | F10: =E10/F4 -> 75
E11: =E10-D11+C11 -> 3600 | F11: =E11/F4 -> 75
E12: =E11-D12+C12 -> 3600 | F12: =E12/F4 -> 75
E13: =E12-D13+C13 -> 3600 | F13: =E13/F4 -> 75
E14: =E13-D14+C14 -> 3600 | F14: =E14/F4 -> 75
E15: =E14-D15+C15 -> 3600 | F15: =E15/F4 -> 75
E16: =E15-D16+C16 -> 3600 | F16: =E16/F4 -> 75
E17: =E16-D17+C17 -> 3600 | F17: =E17/F4 -> 75
E18: =E17-D18+C18 -> 3600 | F18: =E18/F4 -> 75
E19: =E18-D19+C19 -> 3600 | F19: =E19/F4 -> 75
E20: =E19-D20+C20 -> 3600 | F20: =E20/F4 -> 75
E21: =E20-D21+C21 -> 3600 | F21: =E21/F4 -> 75
E22: =E21-D22+C22 -> 3600 | F22: =E22/F4 -> 75
E23: =E22-D23+C23 -> 3600 | F23: =E23/F4 -> 75
E24: =E23-D24+C24 -> 3600 | F24: =E24/F4 -> 75
E25: =E24-D25+C25 -> 3600 | F25: =E25/F4 -> 75
E26: =E25-D26+C26 -> 3600 | F26: =E26/F4 -> 75
E27: =E26-D27+C27 -> 3600 | F27: =E27/F4 -> 75
E28: =E27-D28+C28 -> 3600 | F28: =E28/F4 -> 75
E29: =E28-D29+C29 -> 3600 | F29: =E29/F4 -> 75
E30: =E29-D30+C30 -> 3600 | F30: =E30/F4 -> 75
E31: =E30-D31+C31 -> 3600 | F31: =E31/F4 -> 75
E32: =E31-D32+C32 -> 3600 | F32: =E32/F4 -> 75
E33: =E32-D33+C33 -> 3600 | F33: =E33/F4 -> 75
E34: =E33-D34+C34 -> 3600 | F34: =E34/F4 -> 75
E35: =E34-D35+C35 -> 3600 | F35: =E35/F4 -> 75
E36: =E35-D36+C36 -> 3600 | F36: =E36/F4 -> 75
E37: =E36-D37+C37 -> 3600 | F37: =E37/F4 -> 75
E38: =E37-D38+C38 -> 3600 | F38: =E38/F4 -> 75
E39: =E38-D39+C39 -> 3600 | F39: =E39/F4 -> 75
E40: =E39-D40+C40 -> 3600 | F40: =E40/F4 -> 75
E41: =E40-D41+C41 -> 3600 | F41: =E41/F4 -> 75
...

Sheet PARFUME BLOSSOM 100ML
A1: PARFUME BLOSSOM 100ML
A3: DATE | B3: DÉSIGNATION | C3: RENTRÉ | D3: SOTIE | E3: BALANCE | F3: BALANCE / CNT
A4: 46241 | E4: 3936 | F4: 48
A5: 46241 | B5: LALIT | D5: 240 | E5: =E4-D5+C5 -> 3696 | F5: =E5/F4 -> 77
A6: 46245 | B6: SALIOU | D6: 48 | E6: =E5-D6+C6 -> 3648 | F6: =E6/F4 -> 76
B7: ISMAİËL | D7: 48 | E7: =E6-D7+C7 -> 3600 | F7: =E7/F4 -> 75
E8: =E7-D8+C8 -> 3600 | F8: =E8/F4 -> 75
E9: =E8-D9+C9 -> 3600 | F9: =E9/F4 -> 75
E10: =E9-D10+C10 -> 3600 | F10: =E10/F4 -> 75
E11: =E10-D11+C11 -> 3600 | F11: =E11/F4 -> 75
E12: =E11-D12+C12 -> 3600 | F12: =E12/F4 -> 75
E13: =E12-D13+C13 -> 3600 | F13: =E13/F4 -> 75
E14: =E13-D14+C14 -> 3600 | F14: =E14/F4 -> 75
E15: =E14-D15+C15 -> 3600 | F15: =E15/F4 -> 75
E16: =E15-D16+C16 -> 3600 | F16: =E16/F4 -> 75
E17: =E16-D17+C17 -> 3600 | F17: =E17/F4 -> 75
E18: =E17-D18+C18 -> 3600 | F18: =E18/F4 -> 75
E19: =E18-D19+C19 -> 3600 | F19: =E19/F4 -> 75
E20: =E19-D20+C20 -> 3600 | F20: =E20/F4 -> 75
E21: =E20-D21+C21 -> 3600 | F21: =E21/F4 -> 75
E22: =E21-D22+C22 -> 3600 | F22: =E22/F4 -> 75
E23: =E22-D23+C23 -> 3600 | F23: =E23/F4 -> 75
E24: =E23-D24+C24 -> 3600 | F24: =E24/F4 -> 75
E25: =E24-D25+C25 -> 3600 | F25: =E25/F4 -> 75
E26: =E25-D26+C26 -> 3600 | F26: =E26/F4 -> 75
E27: =E26-D27+C27 -> 3600 | F27: =E27/F4 -> 75
E28: =E27-D28+C28 -> 3600 | F28: =E28/F4 -> 75
E29: =E28-D29+C29 -> 3600 | F29: =E29/F4 -> 75
E30: =E29-D30+C30 -> 3600 | F30: =E30/F4 -> 75
E31: =E30-D31+C31 -> 3600 | F31: =E31/F4 -> 75
E32: =E31-D32+C32 -> 3600 | F32: =E32/F4 -> 75
E33: =E32-D33+C33 -> 3600 | F33: =E33/F4 -> 75
E34: =E33-D34+C34 -> 3600 | F34: =E34/F4 -> 75
E35: =E34-D35+C35 -> 3600 | F35: =E35/F4 -> 75
E36: =E35-D36+C36 -> 3600 | F36: =E36/F4 -> 75
E37: =E36-D37+C37 -> 3600 | F37: =E37/F4 -> 75
E38: =E37-D38+C38 -> 3600 | F38: =E38/F4 -> 75
E39: =E38-D39+C39 -> 3600 | F39: =E39/F4 -> 75
E40: =E39-D40+C40 -> 3600 | F40: =E40/F4 -> 75
E41: =E40-D41+C41 -> 3600 | F41: =E41/F4 -> 75
...

Sheet PARFUME OUD 100ML
A1: PARFUME OUD 100ML
A3: DATE | B3: DÉSIGNATION | C3: RENTRÉ | D3: SOTIE | E3: BALANCE | F3: BALANCE / CNT
A4: 46241 | E4: 3888 | F4: 48
A5: 46241 | B5: LALIT | D5: 240 | E5: =E4-D5+C5 -> 3648 | F5: =E5/F4 -> 76
A6: 46245 | B6: SALIOU | D6: 48 | E6: =E5-D6+C6 -> 3600 | F6: =E6/F4 -> 75
B7: ISMAİËL | D7: 48 | E7: =E6-D7+C7 -> 3552 | F7: =E7/F4 -> 74
E8: =E7-D8+C8 -> 3552 | F8: =E8/F4 -> 74
E9: =E8-D9+C9 -> 3552 | F9: =E9/F4 -> 74
E10: =E9-D10+C10 -> 3552 | F10: =E10/F4 -> 74
E11: =E10-D11+C11 -> 3552 | F11: =E11/F4 -> 74
E12: =E11-D12+C12 -> 3552 | F12: =E12/F4 -> 74
E13: =E12-D13+C13 -> 3552 | F13: =E13/F4 -> 74
E14: =E13-D14+C14 -> 3552 | F14: =E14/F4 -> 74
E15: =E14-D15+C15 -> 3552 | F15: =E15/F4 -> 74
E16: =E15-D16+C16 -> 3552 | F16: =E16/F4 -> 74
E17: =E16-D17+C17 -> 3552 | F17: =E17/F4 -> 74
E18: =E17-D18+C18 -> 3552 | F18: =E18/F4 -> 74
E19: =E18-D19+C19 -> 3552 | F19: =E19/F4 -> 74
E20: =E19-D20+C20 -> 3552 | F20: =E20/F4 -> 74
E21: =E20-D21+C21 -> 3552 | F21: =E21/F4 -> 74
E22: =E21-D22+C22 -> 3552 | F22: =E22/F4 -> 74
E23: =E22-D23+C23 -> 3552 | F23: =E23/F4 -> 74
E24: =E23-D24+C24 -> 3552 | F24: =E24/F4 -> 74
E25: =E24-D25+C25 -> 3552 | F25: =E25/F4 -> 74
E26: =E25-D26+C26 -> 3552 | F26: =E26/F4 -> 74
E27: =E26-D27+C27 -> 3552 | F27: =E27/F4 -> 74
E28: =E27-D28+C28 -> 3552 | F28: =E28/F4 -> 74
E29: =E28-D29+C29 -> 3552 | F29: =E29/F4 -> 74
E30: =E29-D30+C30 -> 3552 | F30: =E30/F4 -> 74
E31: =E30-D31+C31 -> 3552 | F31: =E31/F4 -> 74
E32: =E31-D32+C32 -> 3552 | F32: =E32/F4 -> 74
E33: =E32-D33+C33 -> 3552 | F33: =E33/F4 -> 74
E34: =E33-D34+C34 -> 3552 | F34: =E34/F4 -> 74
E35: =E34-D35+C35 -> 3552 | F35: =E35/F4 -> 74
E36: =E35-D36+C36 -> 3552 | F36: =E36/F4 -> 74
E37: =E36-D37+C37 -> 3552 | F37: =E37/F4 -> 74
E38: =E37-D38+C38 -> 3552 | F38: =E38/F4 -> 74
E39: =E38-D39+C39 -> 3552 | F39: =E39/F4 -> 74
E40: =E39-D40+C40 -> 3552 | F40: =E40/F4 -> 74
E41: =E40-D41+C41 -> 3552 | F41: =E41/F4 -> 74
...

Sheet PRINCESS CREAM C.B M S 260ML 
A1: PRINCESS CREAM C.B M/S 260ML
A3: DATE | B3: PARTICULARS | C3: IN | D3: OUT | E3: BALANCE
E4: 522
A5: 44930 | B5: MODY BOBO | D5: 72 | E5: =E4-D5+C5 -> 450
A6: 44940 | B6: MAMADOU BAILO | D6: 144 | E6: =E5-D6+C6 -> 306
A7: 44942 | B7: BOUBACAR COSMATIQUE | D7: 72 | E7: =E6-D7+C7 -> 234
A8: 44943 | B8: WAREHOUSE | D8: 72 | E8: =E7-D8+C8 -> 162
A9: 44945 | B9: MAMDOU SALIOU | D9: 72 | E9: =E8-D9+C9 -> 90
A10: 44946 | B10: THIERNO BARRY COSMATIQUE | D10: 72 | E10: =E9-D10+C10 -> 18
A11: 44953 | B11: SHOP | C11: 720 | E11: =E10-D11+C11 -> 738
A12: 44960 | B12: CASH SALE | D12: 72 | E12: =E11-D12+C12 -> 666
A13: 44986 | B13: KORKA COSMATIQUE | D13: 144 | E13: =E12-D13+C13 -> 522
A14: 45006 | B14: MAMADOU DIAN | D14: 72 | E14: =E13-D14+C14 -> 450
A15: 45024 | B15: ADOULAYE COSMATIQUE | D15: 36 | E15: =E14-D15+C15 -> 414
A16: 45054 | B16: CASH SALE | D16: 216 | E16: =E15-D16+C16 -> 198
A17: 45059 | B17: SYLLA COSMATIQUE | D17: 72 | E17: =E16-D17+C17 -> 126
A18: 45073 | B18: RECED FROM WAREHOUSE | C18: 144 | E18: =E17-D18+C18 -> 270
A19: 45094 | B19: SULEMAN DANBATA | D19: 72 | E19: =E18-D19+C19 -> 198
A20: 45101 | B20: KORKA COSMATIQUE | D20: 144 | E20: =E19-D20+C20 -> 54
A21: 45113 | B21: MAMADOU BAILO | D21: 54 | E21: =E20-D21+C21 -> 0
E22: =E21-D22+C22 -> 0

Sheet PRINCESS CREAM C.B S S 150ML 
A1: PRINCESS CREAM C.B S/S 150ML
A3: DATE | B3: PARTICULARS | C3: IN | D3: OUT | E3: BALANCE
E4: 447
A5: 44930 | B5: MODY BOBO | D5: 72 | E5: =E4-D5+C5 -> 375
A6: 44931 | B6: MADIOU COSMATIQUE | D6: 72 | E6: =E5-D6+C6 -> 303
A7: 44933 | B7: CASH SALE | D7: 72 | E7: =E6-D7+C7 -> 231
A8: 44939 | B8: THIERNO BARRY COSMATIQUE | D8: 24 | E8: =E7-D8+C8 -> 207
A9: 44940 | B9: MAMADOU BAILO | D9: 72 | E9: =E8-D9+C9 -> 135
A10: 44942 | B10: BOUBACAR COSMATIQUE | D10: 72 | E10: =E9-D10+C10 -> 63
A11: 44943 | B11: RECED FROM WAREHOUSE | C11: 71 | E11: =E10-D11+C11 -> 134
A12: 44943 | B12: SACKO PROMOTION | D12: 11 | E12: =E11-D12+C12 -> 123
A13: 44953 | B13: RECED FROM WAREHOUSE | C13: 720 | E13: =E12-D13+C13 -> 843
A14: 44953 | B14: MAMADOU DIAN | D14: 144 | E14: =E13-D14+C14 -> 699
A15: 44978 | B15: IBRAHIMA KADER COSMATICE | D15: 72 | E15: =E14-D15+C15 -> 627
A16: 44982 | B16: IBRAHIMA KADER COSMATICE | D16: 72 | E16: =E15-D16+C16 -> 555
A17: 44984 | B17: IBRAHIMA KADER COSMATICE | D17: 72 | E17: =E16-D17+C17 -> 483
A18: 44985 | B18: MAMADOU YERO COSMATIQUE | D18: 72 | E18: =E17-D18+C18 -> 411
A19: 44986 | B19: KORKA COSMATIQUE | D19: 144 | E19: =E18-D19+C19 -> 267
A20: 44987 | B20: RECED FROM WAREHOUSE | C20: 720 | E20: =E19-D20+C20 -> 987
A21: 45002 | B21: KORKA COSMATIQUE | D21: 144 | E21: =E20-D21+C21 -> 843
A22: 45002 | B22: ADOULAYE DIALLO COSMATIQUE | D22: 144 | E22: =E21-D22+C22 -> 699
A23: 45006 | B23: MAMADOU DIAN | D23: 72 | E23: =E22-D23+C23 -> 627
A24: 45026 | B24: MODY BOBO | D24: 72 | E24: =E23-D24+C24 -> 555
A25: 45047 | B25: MAMADOU YERO COSMATIQUE | D25: 144 | E25: =E24-D25+C25 -> 411
A26: 45054 | B26: CASH SALE | D26: 240 | E26: =E25-D26+C26 -> 171
A27: 45073 | B27: RECED FROM WAREHOUSE | C27: 144 | E27: =E26-D27+C27 -> 315
A28: 45101 | B28: KORKA COSMATIQUE | D28: 144 | E28: =E27-D28+C28 -> 171
A29: 45117 | B29: KORKA COSMATIQUE | D29: 144 | E29: =E28-D29+C29 -> 27
D30: 27 | E30: =E29-D30+C30 -> 0
E31: =E30-D31+C31 -> 0
E32: =E31-D32+C32 -> 0
E33: =E32-D33+C33 -> 0
E34: =E33-D34+C34 -> 0

Sheet  CARRO PAA PRINCESS B S 460ML 
A1: CARRO PAA PRINCESS B/S 460ML
A3: DATE | B3: PARTICULARS | C3: IN | D3: OUT | E3: BALANCE
E4: 56
A5: 44937 | B5: THIERNO BARRY COSMATIQUE | D5: 24 | E5: =E4-D5+C5 -> 32
A6: 44938 | B6: RECED FROM WAREHOUSE | C6: 48 | E6: =E5-D6+C6 -> 80
A7: 44938 | B7: THIERNO BARRY COSMATIQUE | D7: 48 | E7: =E6-D7+C7 -> 32
A8: 44940 | B8: RECED FROM WAREHOUSE | C8: 48 | E8: =E7-D8+C8 -> 80
A9: 44942 | B9: BOUBACAR COSMATIQUE | D9: 24 | E9: =E8-D9+C9 -> 56
A10: 44943 | B10: SACKO PROMOTION | D10: 1 | E10: =E9-D10+C10 -> 55
A11: 44581 | B11: CASH SALE | D11: 1 | E11: =E10-D11+C11 -> 54
A12: 44599 | B12: RECED FROM WAREHOUSE | C12: 336 | E12: =E11-D12+C12 -> 390
A13: 44599 | B13: IBRAHIMA KADER COSMATICE | D13: 48 | E13: =E12-D13+C13 -> 342
A14: 44599 | B14: MONTAGA COSMATIQUE | D14: 48 | E14: =E13-D14+C14 -> 294
A15: 44968 | B15: MAMDOU SALIOU | D15: 48 | E15: =E14-D15+C15 -> 246
A16: 45005 | B16: ADOULAYE COSMATIQUE | D16: 48 | E16: =E15-D16+C16 -> 198
A17: 45024 | B17: ADOULAYE COSMATIQUE | D17: 48 | E17: =E16-D17+C17 -> 150
A18: 45035 | B18: AMADOU OURY | D18: 24 | E18: =E17-D18+C18 -> 126
A19: 45047 | B19: MAMADOU YERO COSMATIQUE | D19: 48 | E19: =E18-D19+C19 -> 78
A20: 45059 | B20: SYLLA COSMATIQUE | D20: 48 | E20: =E19-D20+C20 -> 30
A21: 45065 | B21: MAMDOU SALIOU | D21: 30 | E21: =E20-D21+C21 -> 0
E22: =E21-D22+C22 -> 0
E23: =E22-D23+C23 -> 0
E24: =E23-D24+C24 -> 0
E25: =E24-D25+C25 -> 0
E26: =E25-D26+C26 -> 0
E27: =E26-D27+C27 -> 0

Sheet  CARRO PAA PRINCESS M S 260ML 
A1: CARRO PAA PRINCESS M/S 260ML
A3: DATE | B3: PARTICULARS | C3: IN | D3: OUT | E3: BALANCE
E4: 157
A5: 44943 | B5: RECED FROM WAREHOUSE | C5: 216 | E5: =E4-D5+C5 -> 373
A6: 45024 | B6: ADOULAYE COSMATIQUE | D6: 36 | E6: =E5-D6+C6 -> 337
A7: 45059 | B7: SYLLA COSMATIQUE | D7: 72 | E7: =E6-D7+C7 -> 265
D8: 265 | E8: =E7-D8+C8 -> 0
E9: =E8-D9+C9 -> 0
E10: =E9-D10+C10 -> 0
E11: =E10-D11+C11 -> 0
E12: =E11-D12+C12 -> 0
E13: =E12-D13+C13 -> 0

Sheet CARRO PAA PRINCESS S S 150ML 
A1: CARRO PAA PRINCESS S/S 150ML
A3: DATE | B3: PARTICULARS | C3: IN | D3: OUT | E3: BALANCE
E4: 313
A5: 44939 | B5: THIERNO BARRY COSMATIQUE | D5: 24 | E5: =E4-D5+C5 -> 289
A6: 44943 | B6: SACKO PROMOTION | D6: 2 | E6: =E5-D6+C6 -> 287
A7: 44968 | B7: ELH.OUSMANE COSMATICE | D7: 72 | E7: =E6-D7+C7 -> 215
A8: 44968 | B8: RECED FROM WAREHOUSE | C8: 720 | E8: =E7-D8+C8 -> 935
D9: 935 | E9: =E8-D9+C9 -> 0
E10: =E9-D10+C10 -> 0
E11: =E10-D11+C11 -> 0
E12: =E11-D12+C12 -> 0
E13: =E12-D13+C13 -> 0
E14: =E13-D14+C14 -> 0

Sheet CARRO PAA LOTION B S 400ML 
A1: CARRO PAA LOTION B/S 400ML
A3: DATE | B3: PARTICULARS | C3: IN | D3: OUT | E3: BALANCE
E4: 200
A5: 44943 | B5: SACKO PROMOTION | D5: 1 | E5: =E4-D5+C5 -> 199
A6: 45059 | B6: SYLLA COSMATIQUE | D6: 48 | E6: =E5-D6+C6 -> 151
A7: 45077 | B7: DAMAGE STOCK | D7: 4 | E7: =E6-D7+C7 -> 147
D8: 147 | E8: =E7-D8+C8 -> 0

Sheet CARRO PAA LOTION S S 260ML 
A1: CARRO PAA LOTION S/S 260ML
A3: DATE | B3: PARTICULARS | C3: IN | D3: OUT | E3: BALANCE
E4: 182
A5: 44943 | B5: RECED FROM WAREHOUSE | C5: 60 | E5: =E4-D5+C5 -> 242
A6: 44943 | B6: SACKO PROMOTION | D6: 7 | E6: =E5-D6+C6 -> 235
A7: 45059 | B7: SEND TO FREETOWN | D7: 168 | E7: =E6-D7+C7 -> 67
D8: 67 | E8: =E7-D8+C8 -> 0
E9: =E8-D9+C9 -> 0
E10: =E9-D10+C10 -> 0
E11: =E10-D11+C11 -> 0

Sheet KLEANZ HAND SANITIZER 100 ML 
A1: KLEANZ HAND SANITIZER 100 ML
A3: DATE | B3: PARTICULARS | C3: IN | D3: OUT | E3: BALANCE
E4: 98
A5: 44932 | B5: CASH SALE | D5: 62 | E5: =E4-D5+C5 -> 36
A6: 44932 | B6: SAMPLE USE | D6: 6 | E6: =E5-D6+C6 -> 30
A7: 45097 | B7: KORKA COSMATIQUE | D7: 30 | E7: =E6-D7+C7 -> 0
E8: =E7-D8+C8 -> 0

Sheet KLEANZ HAND SANITIZER 50 ML
A1: KLEANZ HAND SANITIZER 50 ML
A3: DATE | B3: PARTICULARS | C3: IN | D3: OUT | E3: BALANCE
E4: 91
A5: 44932 | B5: CASH SALE | D5: 72 | E5: =E4-D5+C5 -> 19
A6: 44932 | B6: SAMPLE USE | D6: 1 | E6: =E5-D6+C6 -> 18
A7: 45097 | B7: KORKA COSMATIQUE | D7: 18 | E7: =E6-D7+C7 -> 0
E8: =E7-D8+C8 -> 0
E9: =E8-D9+C9 -> 0
E10: =E9-D10+C10 -> 0
E11: =E10-D11+C11 -> 0
E12: =E11-D12+C12 -> 0
E13: =E12-D13+C13 -> 0
E14: =E13-D14+C14 -> 0
E15: =E14-D15+C15 -> 0

Sheet HABIBA PDE B S 250 ML
A1: HABIBA PDE B/S 250ML
A3: DATE | B3: PARTICULARS | C3: IN | D3: OUT | E3: BALANCE
E4: 214
A5: 44943 | B5: SACKO PROMOTION | D5: 4 | E5: =E4-D5+C5 -> 210
A6: 44972 | B6: MODY BOBO | D6: 72 | E6: =E5-D6+C6 -> 138
A7: 45059 | B7: SEND TO FREETOWN | D7: 130 | E7: =E6-D7+C7 -> 8
A8: 45097 | B8: KORKA COSMATIUE | D8: 8 | E8: =E7-D8+C8 -> 0
E9: =E8-D9+C9 -> 0
E10: =E9-D10+C10 -> 0

Sheet HABIBA PDE S S 150 ML
A1: HABIBA PDE S/S 150ML
A3: DATE | B3: PARTICULARS | C3: IN | D3: OUT | E3: BALANCE
E4: 102
A5: 44943 | B5: SACKO PROMOTION | D5: 8 | E5: =E4-D5+C5 -> 94
A6: 44946 | B6: CASH SALE | D6: 1 | E6: =E5-D6+C6 -> 93
D7: 93 | E7: =E6-D7+C7 -> 0
E97: 216

Sheet HABIBA SHEA BUTTER PDE B S 250
A1: HABIBA SHEA BUTTER PDE B/S 250ML
A3: DATE | B3: PARTICULARS | C3: IN | D3: OUT | E3: BALANCE
E4: 72
A5: 44879 | B5: RECED FROM WAREHOUSE | C5: 144 | E5: =E4-D5+C5 -> 216
A6: 44943 | B6: SACKO PROMOTION | D6: 6 | E6: =E5-D6+C6 -> 210
A7: 45059 | B7: SYLLA COSMATIQUE | D7: 66 | E7: =E6-D7+C7 -> 144
A8: 45059 | B8: SEND TO FREETOWN | D8: 135 | E8: =E7-D8+C8 -> 9
A9: 45097 | B9: KORKA COSMATIUE | D9: 9 | E9: =E8-D9+C9 -> 0
E10: =E9-D10+C10 -> 0
E11: =E10-D11+C11 -> 0
E12: =E11-D12+C12 -> 0
E13: =E12-D13+C13 -> 0

Sheet STYLE UP 3 IN 1 SHOWER GEL ICE 
A1: STYLE UP 3 IN 1 SHOWER GEL ACTIVE ICE 420ML
A3: DATE | B3: PARTICULARS | C3: IN | D3: OUT | E3: BALANCE
E4: 10
A5: 44943 | B5: RECED FROM WAREHOUSE | C5: 192 | E5: =E4-D5+C5 -> 202
A6: 44943 | B6: SACKO PROMOTION | D6: 10 | E6: =E5-D6+C6 -> 192
A7: 44964 | B7: BOUBACAR COSMATIQUE | D7: 192 | E7: =E6-D7+C7 -> 0
E8: =E7-D8+C8 -> 0
E9: =E8-D9+C9 -> 0
E10: =E9-D10+C10 -> 0
E11: =E10-D11+C11 -> 0
E12: =E11-D12+C12 -> 0
E13: =E12-D13+C13 -> 0
E14: =E13-D14+C14 -> 0
E15: =E14-D15+C15 -> 0
E16: =E15-D16+C16 -> 0
E17: =E16-D17+C17 -> 0

Sheet STYLE UP 3 IN1 SHOWER GEL FRESH
A1: STYLE UP 3 IN 1 SHOWER GEL FRESH 420ML
A3: DATE | B3: PARTICULARS | C3: IN | D3: OUT | E3: BALANCE
E4: 64
A5: 44964 | B5: RECED FROM WAREHOUSE | C5: 240 | E5: =E4-D5+C5 -> 304
A6: 44964 | B6: MOMTAGA COSMATIQUE | D6: 144 | E6: =E5-D6+C6 -> 160
A7: 44964 | B7: LAMINE COSMATIQUE | D7: 48 | E7: =E6-D7+C7 -> 112
A8: 44970 | B8: THIERNO BARRY COSMATIQUE | D8: 96 | E8: =E7-D8+C8 -> 16
A9: 45065 | B9: CASH SALE | D9: 14 | E9: =E8-D9+C9 -> 2
A10: 45093 | B10: CASH SALE | D10: 2 | E10: =E9-D10+C10 -> 0
E11: =E10-D11+C11 -> 0
E12: =E11-D12+C12 -> 0

Sheet STYLE UP 3 IN1 SHOWER GEL SPORT
A1: STYLE UP 3 IN 1 SHOWER GEL SPORT 420ML
A3: DATE | B3: PARTICULARS | C3: IN | D3: OUT | E3: BALANCE
E4: 64
A5: 44943 | B5: SACKO PROMOTION | D5: 6 | E5: =E4-D5+C5 -> 58
A6: 44972 | B6: THIERNO OUMAR BOUNAYA COSMATIQUE | D6: 48 | E6: =E5-D6+C6 -> 10
A7: 44974 | B7: RECED FROM WAREOUSE | C7: 240 | E7: =E6-D7+C7 -> 250
A8: 44974 | B8: BAH MHAMADOU COSMATIQUE | D8: 48 | E8: =E7-D8+C8 -> 202
A9: 44975 | B9: MADIOU COSMATIQUE | D9: 48 | E9: =E8-D9+C9 -> 154
A10: 44979 | B10: SOULEMANE DANBATA | D10: 48 | E10: =E9-D10+C10 -> 106
A11: 44985 | B11: THIERNO OUMAR BOUNAYAH | D11: 96 | E11: =E10-D11+C11 -> 10
A12: 45093 | B12: CASH SALE | D12: 10 | E12: =E11-D12+C12 -> 0
E13: =E12-D13+C13 -> 0

Sheet STYLE UP SHOWER GEL FOCUS 1050
A1: STYLE UP SHOWER GEL FOCUS 1050ML
A3: DATE | B3: PARTICULARS | C3: IN | D3: OUT | E3: BALANCE
A4: 44870 | B4: STYLE UP SHOWER GEL FOCUS 1050ML | C4: 80 | E4: =C4 -> 80
A5: 44872 | B5: USD SIDHI COSMETICS | D5: 20 | E5: =E4-D5+C5 -> 60
A6: 44873 | B6: MADAM BARRY COSMATIQUE | D6: 20 | E6: =E5-D6+C6 -> 40
A7: 44882 | B7: MADAM BARRY COSMATIQUE | D7: 25 | E7: =E6-D7+C7 -> 15
A8: 44884 | B8: RECED FROM WAREHOUSE | C8: 60 | E8: =E7-D8+C8 -> 75
A9: 44887 | B9: USD SIDHI COSMETICS | D9: 20 | E9: =E8-D9+C9 -> 55
A10: 44889 | B10: SULEMAN COSMATIQUE | D10: 20 | E10: =E9-D10+C10 -> 35
A11: 44901 | B11: BAH MHAMADOU COSMATIQUE | D11: 20 | E11: =E10-D11+C11 -> 15
A12: 44903 | B12: RECED FROM WAREHOUSE | C12: 60 | E12: =E11-D12+C12 -> 75
A13: 44903 | B13: MAMDOU SALIOU | D13: 20 | E13: =E12-D13+C13 -> 55
A14: 44905 | B14: BOUBACAR COSMATIQUE | D14: 40 | E14: =E13-D14+C14 -> 15
A15: 44905 | B15: DAMAGE IN CTN | D15: 6 | E15: =E14-D15+C15 -> 9
A16: 44909 | B16: WEEKEND MART | D16: 6 | E16: =E15-D16+C16 -> 3
A17: 44911 | B17: CASH SALE | D17: 3 | E17: =E16-D17+C17 -> 0
A18: 44943 | B18: RECED FROM WAREHOUSE | C18: 3 | E18: =E17-D18+C18 -> 3
A19: 44985 | B19: CASH SALE | D19: 3 | E19: =E18-D19+C19 -> 0
A20: 45080 | B20: RECED FROM WAREHOUSE | C20: 40 | E20: =E19-D20+C20 -> 40
A21: 45080 | B21: IBRAHIM DANBATA | D21: 4 | E21: =E20-D21+C21 -> 36
A22: 45082 | B22: SULEMAN DANBATA | D22: 8 | E22: =E21-D22+C22 -> 28
A23: 45096 | B23: MODY BOBO | D23: 20 | E23: =E22-D23+C23 -> 8
A24: 45100 | B24: THIERNO OUMAR COSMATIQUE | D24: 8 | E24: =E23-D24+C24 -> 0
E25: =E24-D25+C25 -> 0
E26: =E25-D26+C26 -> 0
E27: =E26-D27+C27 -> 0
E28: =E27-D28+C28 -> 0
E29: =E28-D29+C29 -> 0
E30: =E29-D30+C30 -> 0

Sheet STYLE UP SHOWER GEL SPORT 1050
A1: STYLE UP SHOWER GEL SPORT 1050ML
A3: DATE | B3: PARTICULARS | C3: IN | D3: OUT | E3: BALANCE
E4: 6
A5: 44943 | B5: RECED FROM WAREHOUSE | C5: 45 | E5: =E4-D5+C5 -> 51
A6: 44943 | B6: SACKO PROMOTION | D6: 40 | E6: =E5-D6+C6 -> 11
A7: 45002 | B7: THIERNO BARRY COSMATIQUE | D7: 2 | E7: =E6-D7+C7 -> 9
A8: 45020 | B8: CASH SALE | D8: 1 | E8: =E7-D8+C8 -> 8
A9: 45080 | B9: RECED FROM WAREHOUSE | C9: 40 | E9: =E8-D9+C9 -> 48
A10: 45080 | B10: IBRAHIM DANBATA | D10: 4 | E10: =E9-D10+C10 -> 44
A11: 45082 | B11: SULEMAN DANBATA | D11: 8 | E11: =E10-D11+C11 -> 36
A12: 45091 | B12: CASH SALE | D12: 20 | E12: =E11-D12+C12 -> 16
A13: 45111 | B13: LAMINE COSMATIQUE | D13: 10 | E13: =E12-D13+C13 -> 6
D14: 6 | E14: =E13-D14+C14 -> 0
E15: =E14-D15+C15 -> 0

Sheet STYLEUP SHOWER GEL STAMINA 1050
A1: STYLE UP SHOWER GEL STAMINA 1050ML
A3: DATE | B3: PARTICULARS | C3: IN | D3: OUT | E3: BALANCE
E4: 0
A5: 44943 | B5: RECED FROM WAREHOUSE | C5: 20 | E5: =E4-D5+C5 -> 20
A6: 44943 | B6: SACKO PROMOTION | D6: 20 | E6: =E5-D6+C6 -> 0
A7: 45080 | B7: RECED FROM WAREHOUSE | C7: 40 | E7: =E6-D7+C7 -> 40
A8: 45080 | B8: IBRAHIM DANBATA | D8: 4 | E8: =E7-D8+C8 -> 36
A9: 45082 | B9: SULEMAN DANBATA | D9: 8 | E9: =E8-D9+C9 -> 28
A10: 45094 | B10: THIERNO BARRY COSMATIQUE | D10: 20 | E10: =E9-D10+C10 -> 8
A11: 45100 | B11: THIERNO OUMAR COSMATIQUE | D11: 8 | E11: =E10-D11+C11 -> 0
E12: =E11-D12+C12 -> 0
E13: =E12-D13+C13 -> 0
E14: =E13-D14+C14 -> 0
E15: =E14-D15+C15 -> 0

Sheet STYLE UP SHOWER GEL POWER 1050
A1: STYLE UP SHOWER GEL POWER 1050ML
A3: DATE | B3: PARTICULARS | C3: IN | D3: OUT | E3: BALANCE
A4: 45080 | B4: STYLE UP SHOWER GEL POWER 1050ML | C4: 40 | E4: =C4 -> 40
A5: 45080 | B5: IBRAHIMA DANABATA | D5: 4 | E5: =E4-D5+C5 -> 36
A6: 45082 | B6: SULEMAN DANBATA | D6: 8 | E6: =E5-D6+C6 -> 28
A7: 45092 | B7: IBRAHIMA KADER | D7: 20 | E7: =E6-D7+C7 -> 8
A8: 45093 | B8: CASH SALE | D8: 7 | E8: =E7-D8+C8 -> 1
A9: 45100 | B9: THIERNO OUMAR | D9: 1 | E9: =E8-D9+C9 -> 0
E10: =E9-D10+C10 -> 0
E11: =E10-D11+C11 -> 0
E12: =E11-D12+C12 -> 0
E13: =E12-D13+C13 -> 0
E14: =E13-D14+C14 -> 0

Sheet STYLE UP SHOWER GEL RELAX 1050
A1: STYLE UP SHOWER GEL RELAX 1050ML
A3: DATE | B3: PARTICULARS | C3: IN | D3: OUT | E3: BALANCE
A4: 45080 | B4: STYLE UP SHOWER GEL RELAX 1050ML | C4: 40 | E4: =C4 -> 40
A5: 45080 | B5: IBRAHIMA DANABATA | D5: 4 | E5: =E4-D5+C5 -> 36
A6: 45082 | B6: SULEMAN DANBATA | D6: 8 | E6: =E5-D6+C6 -> 28
A7: 45092 | B7: IBRAHIMA KADER | D7: 20 | E7: =E6-D7+C7 -> 8
A8: 45093 | B8: CASH SALE | D8: 8 | E8: =E7-D8+C8 -> 0
A9: 45099 | B9: RECED FROM WAREHOUSE | C9: 20 | E9: =E8-D9+C9 -> 20
A10: 45100 | B10: THIERNO OUMAR | D10: 7 | E10: =E9-D10+C10 -> 13
A11: 45111 | B11: LAMINE COSMATIQUE | D11: 10 | E11: =E10-D11+C11 -> 3
D12: 3 | E12: =E11-D12+C12 -> 0
E13: =E12-D13+C13 -> 0
E14: =E13-D14+C14 -> 0

Sheet BO-16 HERBAL CARE 280GR 
A1: BO-16 HERBAL CARE 280GR
A3: DATE | B3: PARTICULARS | C3: IN | D3: OUT | E3: BALANCE
E4: 66
A5: 44943 | B5: SACKO PROMOTION | D5: 11 | E5: =E4-D5+C5 -> 55
A6: 44986 | B6: MONTAGA COSMATIQUE | D6: 50 | E6: =E5-D6+C6 -> 5
A7: 45036 | B7: SACKO PROMOTION | D7: 5 | E7: =E6-D7+C7 -> 0
A8: 45093 | B8: RECED FROM WAREHOUSE | C8: 24 | E8: =E7-D8+C8 -> 24
A9: 45093 | B9: CASH SALE | D9: 6 | E9: =E8-D9+C9 -> 18
D10: 18 | E10: =E9-D10+C10 -> 0
E11: =E10-D11+C11 -> 0

Sheet BO-16 HAIR FOOD VITAMINS 225ML
A1: BO-16 HAIR FOOD VITAMINS 225ML
A3: DATE | B3: PARTICULARS | C3: IN | D3: OUT | E3: BALANCE
E4: 48
A5: 44929 | B5: LAMINE COSMATIQUE | D5: 30 | E5: =E4-D5+C5 -> 18
A6: 44943 | B6: SACKO PROMOTION | D6: 2 | E6: =E5-D6+C6 -> 16
A7: 44981 | B7: MONTAGA COSMATIQUE | D7: 16 | E7: =E6-D7+C7 -> 0
A8: 45093 | B8: RECED FROM WAREHOUSE | C8: 32 | E8: =E7-D8+C8 -> 32
A9: 45093 | B9: CASH SALE | D9: 6 | E9: =E8-D9+C9 -> 26
A10: 45125 | B10: THIERNO OUMAR BOUNAYAH COSMATIQUE | D10: 26 | E10: =E9-D10+C10 -> 0
E11: =E10-D11+C11 -> 0
E12: =E11-D12+C12 -> 0
E13: =E12-D13+C13 -> 0
E14: =E13-D14+C14 -> 0

Sheet BO-16 HAIR FOOD 225ML 
A1: BO-16 HAIR FOOD 225ML
A3: DATE | B3: PARTICULARS | C3: IN | D3: OUT | E3: BALANCE
E4: 48
A5: 44929 | B5: LAMINE COSMATIQUE | D5: 32 | E5: =E4-D5+C5 -> 16
A6: 44943 | B6: SACKO PROMOTION | D6: 10 | E6: =E5-D6+C6 -> 6
A7: 44981 | B7: MONTAGA COSMATIQUE | D7: 1 | E7: =E6-D7+C7 -> 5
A8: 44986 | B8: MONTAGA COSMATIQUE | D8: 4 | E8: =E7-D8+C8 -> 1
A9: 45036 | B9: SACKO PROMOTION | D9: 1 | E9: =E8-D9+C9 -> 0
E10: =E9-D10+C10 -> 0
E11: =E10-D11+C11 -> 0
E12: =E11-D12+C12 -> 0

Sheet KLEANZ BODY WASH ALOE VERA 750
A1: KLEANZ BODY WASH ALOE VERA 750ML
A3: DATE | B3: PARTICULARS | C3: IN | D3: OUT | E3: BALANCE
E4: 43
A5: 44943 | B5: SACKO PROMOTION | D5: 6 | E5: =E4-D5+C5 -> 37
A6: 44967 | B6: SIDY COSMATIQUE | D6: 33 | E6: =E5-D6+C6 -> 4
A7: 44967 | B7: RECED FROM WAREHOUSE | C7: 60 | E7: =E6-D7+C7 -> 64
A8: 45001 | B8: CASH SALE | D8: 20 | E8: =E7-D8+C8 -> 44
A9: 45047 | B9: AMADOU OURY COSMATIQUE | D9: 40 | E9: =E8-D9+C9 -> 4
A10: 45055 | B10: CASH SALE | D10: 4 | E10: =E9-D10+C10 -> 0
A11: 45093 | B11: RECED FROM WAREHOUSE | C11: 20 | E11: =E10-D11+C11 -> 20
A12: 45093 | B12: CASH SALE | D12: 4 | E12: =E11-D12+C12 -> 16
D13: 16 | E13: =E12-D13+C13 -> 0
E14: =E13-D14+C14 -> 0
E15: =E14-D15+C15 -> 0
E16: =E15-D16+C16 -> 0
E17: =E16-D17+C17 -> 0

Sheet KLEANZ BODY WASH STRAWBER 750ML
A1: KLEANZ BODY WASH STRAWBERRY 750ML
A3: DATE | B3: PARTICULARS | C3: IN | D3: OUT | E3: BALANCE
E4: 16
A5: 44943 | B5: SACKO PROMOTION | D5: 3 | E5: =E4-D5+C5 -> 13
A6: 44967 | B6: SIDY COSMATIQUE | D6: 13 | E6: =E5-D6+C6 -> 0
A7: 44967 | B7: RECED FROM WAREHOUSE | C7: 60 | E7: =E6-D7+C7 -> 60
A8: 44970 | B8: BAH MHAMADOU COSMATIQUE | D8: 60 | E8: =E7-D8+C8 -> 0
E9: =E8-D9+C9 -> 0

Sheet KLEANZ BODYWASH ANTIBACTIRAL750
A1: KLEANZ BODY WASH ANTIBACTIRAL 750 ML
A3: DATE | B3: PARTICULARS | C3: IN | D3: OUT | E3: BALANCE
E4: 11
A5: 44943 | B5: SACKO PROMOTION | D5: 3 | E5: =E4-D5+C5 -> 8
A6: 44967 | B6: SIDY COSMATIQUE | D6: 8 | E6: =E5-D6+C6 -> 0
A7: 44967 | B7: RECED FROM WAREHOUSE | C7: 60 | E7: =E6-D7+C7 -> 60
A8: 44968 | B8: MAMDOU SALIOU | D8: 40 | E8: =E7-D8+C8 -> 20
A9: 45047 | B9: AMADOU OURY COSMATIQUE | D9: 20 | E9: =E8-D9+C9 -> 0
E10: =E9-D10+C10 -> 0
E11: =E10-D11+C11 -> 0
E12: =E11-D12+C12 -> 0
E13: =E12-D13+C13 -> 0

Sheet KLEANZ BODY WASH VANILLA 750
A1: KLEANZ BODY WASH VANILLA & HONEY 750 ML
A3: DATE | B3: PARTICULARS | C3: IN | D3: OUT | E3: BALANCE
E4: 0
A5: 44967 | B5: RECED FROM WAREHOUSE | C5: 160 | E5: =E4-D5+C5 -> 160
A6: 44967 | B6: ALPHA MAMOU | D6: 20 | E6: =E5-D6+C6 -> 140
A7: 44985 | B7: THIERNO BARRY COSMATIQUE | D7: 20 | E7: =E6-D7+C7 -> 120
A8: 44995 | B8: SIDY COSMATIQUE | D8: 100 | E8: =E7-D8+C8 -> 20
A9: 45047 | B9: AMADOU OURY COSMATIQUE | D9: 20 | E9: =E8-D9+C9 -> 0
E10: =E9-D10+C10 -> 0
E11: =E10-D11+C11 -> 0

Sheet KLEANZ BODY COCONUT OIL 750ML
A1: KLEANZ BODY COCONUT OIL & CHOCLATE 750ML
A3: DATE | B3: PARTICULARS | C3: IN | D3: OUT | E3: BALANCE
E4: 16
A5: 44943 | B5: SACKO PROMOTION | D5: 10 | E5: =E4-D5+C5 -> 6
A6: 44967 | B6: SIDY COSMATIQUE | D6: 6 | E6: =E5-D6+C6 -> 0
A7: 44967 | B7: RECED FROM WAREHOUSE | C7: 60 | E7: =E6-D7+C7 -> 60
A8: 44968 | B8: MAMDOU SALIOU | D8: 60 | E8: =E7-D8+C8 -> 0
E9: =E8-D9+C9 -> 0
E10: =E9-D10+C10 -> 0
E11: =E10-D11+C11 -> 0
E12: =E11-D12+C12 -> 0
E13: =E12-D13+C13 -> 0
E14: =E13-D14+C14 -> 0
E15: =E14-D15+C15 -> 0

Sheet CLASSIC HAIR PDE S-S 125 ML 
A1: CLASSIC HAIR PDE S-S 125 ML
A3: DATE | B3: PARTICULARS | C3: IN | D3: OUT | E3: BALANCE
E4: 216
A5: 44943 | B5: SACKO PROMOTION | D5: 21 | E5: =E4-D5+C5 -> 195
A6: 45059 | B6: SYLLA COSMATIQUE | D6: 108 | E6: =E5-D6+C6 -> 87
A7: 45073 | B7: RECED FROM WAREHOUSE | C7: 432 | E7: =E6-D7+C7 -> 519
A8: 45100 | B8: SYLLA COSMATIQUE | D8: 24 | E8: =E7-D8+C8 -> 495
D9: 495 | E9: =E8-D9+C9 -> 0

Sheet CLASSIC HAIR PDE B-S 300 ML 
A1: CLASSIC HAIR PDE B-S 300 ML
A3: DATE | B3: PARTICULARS | C3: IN | D3: OUT | E3: BALANCE
E4: 144
A5: 44943 | B5: SACKO PROMOTION | D5: 20 | E5: =E4-D5+C5 -> 124
A6: 44972 | B6: MADAM BARRY COSMATIQUE | D6: 48 | E6: =E5-D6+C6 -> 76
A7: 44972 | B7: MODY BOBO | D7: 48 | E7: =E6-D7+C7 -> 28
A8: 44972 | B8: RECED FROM WAREHOUSE | C8: 240 | E8: =E7-D8+C8 -> 268
A9: 44977 | B9: ELH. ALSENY BARRY COSMATIQUE | D9: 48 | E9: =E8-D9+C9 -> 220
A10: 44977 | B10: SIDY COSMATIQUE | D10: 48 | E10: =E9-D10+C10 -> 172
A11: 44978 | B11: IBRAHIMA KADER COSMATICE | D11: 48 | E11: =E10-D11+C11 -> 124
A12: 44979 | B12: SOULEMANE DANBATA | D12: 48 | E12: =E11-D12+C12 -> 76
A13: 44981 | B13: MONTAGA COSMATIQUE | D13: 48 | E13: =E12-D13+C13 -> 28
A14: 44984 | B14: SOULEMANE DANBATA | D14: 22 | E14: =E13-D14+C14 -> 6
A15: 44987 | B15: SOULEMANE DANBATA | D15: 5 | E15: =E14-D15+C15 -> 1
A16: 45036 | B16: SACKO PROMOTION | D16: 1 | E16: =E15-D16+C16 -> 0
E17: =E16-D17+C17 -> 0
E18: =E17-D18+C18 -> 0
E19: =E18-D19+C19 -> 0

Sheet LAIT NATURE CLAIRE 250ML
A1: LAIT NATURE CLAIRE 250ML
A3: DATE | B3: PARTICULARS | C3: IN | D3: OUT | E3: BALANCE
E4: 132
A5: 44940 | B5: SACKO PROMOTION | D5: 15 | E5: =E4-D5+C5 -> 117
A6: 44960 | B6: CASH SALE | D6: 34 | E6: =E5-D6+C6 -> 83
A7: 45036 | B7: SACKO PROMOTION | D7: 19 | E7: =E6-D7+C7 -> 64
D8: 64 | E8: =E7-D8+C8 -> 0
E9: =E8-D9+C9 -> 0
E10: =E9-D10+C10 -> 0

Sheet LAIT NATURE CLAIRE 500ML
A1: LAIT NATURE CLAIRE 500ML
A3: DATE | B3: PARTICULARS | C3: IN | D3: OUT | E3: BALANCE
E4: 71
A5: 44960 | B5: CASH SALE | D5: 24 | E5: =E4-D5+C5 -> 47
D6: 47 | E6: =E5-D6+C6 -> 0
E7: =E6-D7+C7 -> 0
E8: =E7-D8+C8 -> 0
E9: =E8-D9+C9 -> 0

Sheet GEL D.SKINS BABY CARE
A1: GEL D.SKINS BABY CARE
A3: DATE | B3: PARTICULARS | C3: IN | D3: OUT | E3: BALANCE
E4: 24
A5: 44943 | B5: SACKO PROMOTION | D5: 3 | E5: =E4-D5+C5 -> 21
D6: 21 | E6: =E5-D6+C6 -> 0
E7: =E6-D7+C7 -> 0
E8: =E7-D8+C8 -> 0
E9: =E8/12 -> 0

Sheet LAIT SKIN BABYCARE 750 ML 
A1: LAIT SKIN BABYCARE 750 ML
A3: DATE | B3: PARTICULARS | C3: IN | D3: OUT | E3: BALANCE
E4: 16
A5: 44926 | B5: DAMAGE | D5: 1 | E5: =E4-D5+C5 -> 15
D6: 15 | E6: =E5-D6+C6 -> 0
E7: =E6-D7+C7 -> 0
E8: =E7-D8+C8 -> 0
E9: =E8/12 -> 0

Sheet LAIT SKINS GOLD 210 ML
A1: LAIT SKINS GOLD 210 ML
A3: DATE | B3: PARTICULARS | C3: IN | D3: OUT | E3: BALANCE
A4: 44826 | B4: LAIT SKINS GOLD 210 ML | C4: 72 | E4: =C4 -> 72
A5: 44912 | B5: FREETOWN BRANCH | D5: 36 | E5: =E4-D5+C5 -> 36
D6: 36 | E6: =E5-D6+C6 -> 0
E7: =E6-D7+C7 -> 0
E8: =E7-D8+C8 -> 0
E9: =E8-D9+C9 -> 0
E10: =E9-D10+C10 -> 0
E11: =E10-D11+C11 -> 0
E12: =E11-D12+C12 -> 0
E13: =E12-D13+C13 -> 0
E14: =E13-D14+C14 -> 0
E15: =E14/36 -> 0

Sheet EAU DE BEBE SKINS 535 ML
A1: EAU DE BEBE SKINS 535 ML
A3: DATE | B3: PARTICULARS | C3: IN | D3: OUT | E3: BALANCE
E4: 92
A5: 44930 | B5: CASH SALE | D5: 36 | E5: =E4-D5+C5 -> 56
A6: 44945 | B6: CASH SALE | D6: 24 | E6: =E5-D6+C6 -> 32
A7: 44979 | B7: CASH SALE | D7: 32 | E7: =E6-D7+C7 -> 0
E8: =E7-D8+C8 -> 0
E9: =E8-D9+C9 -> 0
E10: =E9-D10+C10 -> 0
E11: =E10-D11+C11 -> 0
E12: =E11-D12+C12 -> 0
E13: =E12/24 -> 0

Sheet CREME CH. SKINS BABY 150GRS
A1: CREME CH. SKINS BABY 150GRS
A3: DATE | B3: PARTICULARS | C3: IN | D3: OUT | E3: BALANCE
E4: 144
A5: 44943 | B5: SACKO PROMOTION | D5: 2 | E5: =E4-D5+C5 -> 142
A6: 44945 | B6: CASH SALE | D6: 36 | E6: =E5-D6+C6 -> 106
A7: 44979 | B7: CASH SALE | D7: 29 | E7: =E6-D7+C7 -> 77
D8: 77 | E8: =E7-D8+C8 -> 0
E9: =E8-D9+C9 -> 0
E10: =E9-D10+C10 -> 0
E11: =E10-D11+C11 -> 0
E12: =E11-D12+C12 -> 0

Sheet CREME NAT.CLAIRE 150 GRS
A1: CREME NAT.CLAIRE 150 GRS
A3: DATE | B3: PARTICULARS | C3: IN | D3: OUT | E3: BALANCE
E4: 12
A5: 44979 | B5: CASH SALE | D5: 8 | E5: =E4-D5+C5 -> 4
A6: 44987 | B6: LY THIERNO AMADOU COSMATIQUE | D6: 4 | E6: =E5-D6+C6 -> 0
E7: =E6-D7+C7 -> 0
E8: =E7-D8+C8 -> 0
E9: =E8/48 -> 0

Sheet CREME NAT.CLAIRE 300ML
A1: CREME NAT.CLAIRE 300ML
A3: DATE | B3: PARTICULARS | C3: IN | D3: OUT | E3: BALANCE
E4: 1
A5: 44943 | B5: SAMPLE USE | D5: 1 | E5: =E4-D5+C5 -> 0
E6: =E5-D6+C6 -> 0
E7: =E6-D7+C7 -> 0
E8: =E7/24 -> 0

Sheet LIQ.VAISS.CLEANOL 750ML MIX
A1: LIQ.VAISS.CLEANOL 750ML MIX
A3: DATE | B3: PARTICULARS | C3: IN | D3: OUT | E3: BALANCE
E4: 40
A5: 44930 | B5: CASH SALE | D5: 21 | E5: =E4-D5+C5 -> 19
A6: 44932 | B6: CASH SALE | D6: 12 | E6: =E5-D6+C6 -> 7
A7: 45055 | B7: CASH SALE | D7: 7 | E7: =E6-D7+C7 -> 0
E8: =E7-D8+C8 -> 0
E9: =E8/12 -> 0

Sheet LOT SKINS BABY CARE
A1: LOT SKINS BABY CARE
A3: DATE | B3: PARTICULARS | C3: IN | D3: OUT | E3: BALANCE
E4: 22
A5: 44926 | B5: DAMAGE | D5: 6 | E5: =E4-D5+C5 -> 16
D6: 16 | E6: =E5-D6+C6 -> 0
E7: =E6-D7+C7 -> 0

Sheet LAIT SKINS 225ML
A1: LAIT SKINS 225ML
A3: DATE | B3: PARTICULARS | C3: IN | D3: OUT | E3: BALANCE
E4: 324
A5: 44929 | B5: LAMINE COSMATIQUE | D5: 36 | E5: =E4-D5+C5 -> 288
A6: 44936 | B6: ABDUL KARIM COSMATIQUE | D6: 36 | E6: =E5-D6+C6 -> 252
A7: 44940 | B7: SACKO PROMOTION | D7: 30 | E7: =E6-D7+C7 -> 222
A8: 44966 | B8: IBRAHIMA KANBAYA COSMATIQUE | D8: 36 | E8: =E7-D8+C8 -> 186
A9: 44966 | B9: MOUSTAPHA COSMATIQUE | D9: 72 | E9: =E8-D9+C9 -> 114
A10: 44966 | B10: ALPHA MAMAOU | D10: 36 | E10: =E9-D10+C10 -> 78
A11: 45051 | B11: MD.SAIDOU COSMATIQUE | D11: 36 | E11: =E10-D11+C11 -> 42
A12: 45069 | B12: SYLLA COSMATIQUE | D12: 36 | E12: =E11-D12+C12 -> 6
D13: 6 | E13: =E12-D13+C13 -> 0
E14: =E13-D14+C14 -> 0
E15: =E14-D15+C15 -> 0
E16: =E15/36 -> 0

Sheet LAIT SKINS 400ML
A1: LAIT SKINS 400ML
A3: DATE | B3: PARTICULARS | C3: IN | D3: OUT | E3: BALANCE
E4: 264
A5: 44940 | B5: SACKO PROMOTION | D5: 6 | E5: =E4-D5+C5 -> 258
A6: 44966 | B6: IBRAHIMA KANBAYA COSMATIQUE | D6: 24 | E6: =E5-D6+C6 -> 234
A7: 44966 | B7: MOUSTAPHA COSMATIQUE | D7: 24 | E7: =E6-D7+C7 -> 210
A8: 45005 | B8: MONTAGA COSMATIQUE | D8: 24 | E8: =E7-D8+C8 -> 186
A9: 45051 | B9: ISMAIL COSMATIQUE | D9: 24 | E9: =E8-D9+C9 -> 162
A10: 45051 | B10: MD.SAIDOU COSMATIQUE | D10: 24 | E10: =E9-D10+C10 -> 138
A11: 45069 | B11: SYLLA COSMATIQUE | D11: 24 | E11: =E10-D11+C11 -> 114
D12: 114 | E12: =E11-D12+C12 -> 0
E13: =E12-D13+C13 -> 0
E14: =E13-D14+C14 -> 0
E15: =E14/24 -> 0

Sheet SAV.NAT.CLAIRE 400GRS CARROT
A1: SAV.NAT.CLAIRE 400GRS CARROT
A3: DATE | B3: PARTICULARS | C3: IN | D3: OUT | E3: BALANCE
E4: 0
A5: 44949 | B5: RECED FROM WAREHOUSE | C5: 456 | E5: =E4-D5+C5 -> 456
A6: 44622 | B6: LAMINE COSMATIQUE | D6: 24 | E6: =E5-D6+C6 -> 432
A7: 44634 | B7: MAMDOU SALIOU | D7: 96 | E7: =E6-D7+C7 -> 336
A8: 44708 | B8: DIALLO MAMADOU LAMARANA GNF | D8: 125 | E8: =E7-D8+C8 -> 211
D9: 211 | E9: =E8-D9+C9 -> 0
E10: =E9-D10+C10 -> 0
E11: =E10-D11+C11 -> 0
E12: =E11-D12+C12 -> 0
E13: =E12-D13+C13 -> 0
E14: =E13/24 -> 0

Sheet SAV.NAT.CLAIRE 400GRS CITRON 
A1: SAV.NAT.CLAIRE 400GRS CITRON
A3: DATE | B3: PARTICULARS | C3: IN | D3: OUT | E3: BALANCE
E4: 0
A5: 44949 | B5: RECED FROM WAREHOUSE | C5: 96 | E5: =E4-D5+C5 -> 96
A6: 45069 | B6: SYLLA COSMATIQUE | D6: 24 | E6: =E5-D6+C6 -> 72
A7: 45070 | B7: CASH SALE | D7: 2 | E7: =E6-D7+C7 -> 70
A8: 44708 | B8: DIALLO MAMADOU LAMARANA GNF | D8: 70 | E8: =E7-D8+C8 -> 0
E9: =E8-D9+C9 -> 0
E10: =E9-D10+C10 -> 0
E11: =E10/24 -> 0

Sheet SAV.NAT.CLAIRE 400GRS 
A1: SAV.NAT.CLAIRE 400GRS
A3: DATE | B3: PARTICULARS | C3: IN | D3: OUT | E3: BALANCE
E4: 0
A5: 44949 | B5: RECED FROM WAREHOUSE | C5: 408 | E5: =E4-D5+C5 -> 408
A6: 44996 | B6: MADAM BARRY COSMATIQUE | D6: 192 | E6: =E5-D6+C6 -> 216
A7: 45112 | B7: SIDY BAH | D7: 48 | E7: =E6-D7+C7 -> 168
A8: 45167 | B8: LAMINE COSMATIQUW | D8: 168 | E8: =E7-D8+C8 -> 0
E9: =E8-D9+C9 -> 0
E10: =E9-D10+C10 -> 0
E11: =E10/24 -> 0

Sheet SAV.NAT.CLAIRE 400GR COCOA
A1: SAV.NAT.CLAIRE 400GR COCOA
A3: DATE | B3: PARTICULARS | C3: IN | D3: OUT | E3: BALANCE
E4: 0
A5: 44949 | B5: RECED FROM WAREHOUSE | C5: 216 | E5: =E4-D5+C5 -> 216
A6: 44958 | B6: CASH SALE | D6: 24 | E6: =E5-D6+C6 -> 192
A7: 44958 | B7: LAMINE COSMATIQUE | D7: 24 | E7: =E6-D7+C7 -> 168
A8: 44977 | B8: LAMINE COSMATIQUE | D8: 24 | E8: =E7-D8+C8 -> 144
D9: 144 | E9: =E8-D9+C9 -> 0
E10: =E9-D10+C10 -> 0
E11: =E10-D11+C11 -> 0
E12: =E11-D12+C12 -> 0
E13: =E12-D13+C13 -> 0
E14: =E13/24 -> 0

Sheet SAV.NAT.CLAIRE 400GRS ARGAN
A1: SAV.NAT.CLAIRE 400GRS ARGAN
A3: DATE | B3: PARTICULARS | C3: IN | D3: OUT | E3: BALANCE
E4: 0
A5: 44949 | B5: RECED FROM WAREHOUSE | C5: 144 | E5: =E4-D5+C5 -> 144
D6: 144 | E6: =E5-D6+C6 -> 0
E7: =E6/24 -> 0

Sheet SAV.NAT.CLAIRE 400GRS MIEL
A1: SAV.NAT.CLAIRE 400GRS MIEL
A3: DATE | B3: PARTICULARS | C3: IN | D3: OUT | E3: BALANCE
E4: 4
A5: 44943 | B5: SACKO PROMOTION | D5: 4 | E5: =E4-D5+C5 -> 0
A6: 44949 | B6: RECED FROM WAREHOUSE | C6: 72 | E6: =E5-D6+C6 -> 72
A7: 44984 | B7: ADOULAYE DIALLO COSMATIQUE | D7: 72 | E7: =E6-D7+C7 -> 0
E8: =E7-D8+C8 -> 0
E9: =E8/24 -> 0

Sheet SAV.NAT.CLAIRE 400GRS PAPAYE
A1: SAV.NAT.CLAIRE 400GRS PAPAYE
A3: DATE | B3: PARTICULARS | C3: IN | D3: OUT | E3: BALANCE
E4: 12
A5: 44929 | B5: LAMINE COSMATIQUE | D5: 12 | E5: =E4-D5+C5 -> 0
E6: =E5-D6+C6 -> 0
E7: =E6-D7+C7 -> 0
E8: =E7-D8+C8 -> 0
E9: =E8/24 -> 0

Sheet SAV.NAT.CLAIRE 400GRS AVOCAT 
A1: SAV.NAT.CLAIRE 400GRS AVOCAT
A3: DATE | B3: PARTICULARS | C3: IN | D3: OUT | E3: BALANCE
E4: 31
A5: 44929 | B5: LAMINE COSMATIQUE | D5: 12 | E5: =E4-D5+C5 -> 19
A6: 45061 | B6: MADAM BARRY COSMATIQUE | D6: 19 | E6: =E5-D6+C6 -> 0
E7: =E6-D7+C7 -> 0
E8: =E7/24 -> 0

Sheet SAV.NAT.CLAIRE 400GRS LAIT 
A1: SAV.NAT.CLAIRE 400GRS LAIT
A3: DATE | B3: PARTICULARS | C3: IN | D3: OUT | E3: BALANCE
E4: 14
A5: 44929 | B5: LAMINE COSMATIQUE | D5: 12 | E5: =E4-D5+C5 -> 2
A6: 44949 | B6: RECED FROM WAREHOUSE | C6: 120 | E6: =E5-D6+C6 -> 122
A7: 44965 | B7: MADAM BARRY COSMATIQUE | D7: 72 | E7: =E6-D7+C7 -> 50
A8: 45061 | B8: MADAM BARRY COSMATIQUE | D8: 50 | E8: =E7-D8+C8 -> 0
E9: =E8-D9+C9 -> 0
E10: =E9-D10+C10 -> 0
E11: =E10-D11+C11 -> 0
E12: =E11-D12+C12 -> 0
E13: =E12-D13+C13 -> 0
E14: =E13-D14+C14 -> 0
E15: =E14/24 -> 0

Sheet SAV.NAT.CLAIRE 400GRS OLIVE
A1: SAV.NAT.CLAIRE 400GRS OLIVE
A3: DATE | B3: PARTICULARS | C3: IN | D3: OUT | E3: BALANCE
E4: 39
A5: 44929 | B5: LAMINE COSMATIQUE | D5: 12 | E5: =E4-D5+C5 -> 27
A6: 44936 | B6: CASH SALE | D6: 24 | E6: =E5-D6+C6 -> 3
A7: 44943 | B7: SACKO PROMOTION | D7: 3 | E7: =E6-D7+C7 -> 0
A8: 44949 | B8: RECED FROM WAREHOUSE | C8: 168 | E8: =E7-D8+C8 -> 168
A9: 45061 | B9: MADAM BARRY COSMATIQUE | D9: 27 | E9: =E8-D9+C9 -> 141
A10: 44708 | B10: DIALLO MAMADOU LAMARANA GNF | D10: 141 | E10: =E9-D10+C10 -> 0
E11: =E10-D11+C11 -> 0
E12: =E11-D12+C12 -> 0
E13: =E12-D13+C13 -> 0
E14: =E13/24 -> 0

Sheet NATURAL PAPAYA & CARROT SOAP 
A1: Nano Extra White Natural Papaya & Carrot Soap 160gm
A3: DATE | B3: PARTICULARS | C3: IN | D3: OUT | E3: BALANCE
E4: 924
A5: 45005 | B5: MONTAGA COSMATIQUE | D5: 144 | E5: =E4-D5+C5 -> 780
A6: 45070 | B6: CASH SALE | D6: 65 | E6: =E5-D6+C6 -> 715
A7: 45083 | B7: CASH SALE | D7: 75 | E7: =E6-D7+C7 -> 640
A8: 45091 | B8: CASH SALE | D8: 20 | E8: =E7-D8+C8 -> 620
A9: 45093 | B9: MAMADOU SALIOU | D9: 360 | E9: =E8-D9+C9 -> 260
A10: 45103 | B10: CASH SALE | D10: 24 | E10: =E9-D10+C10 -> 236
A11: 45111 | B11: AMADOU BIRO | D11: 24 | E11: =E10-D11+C11 -> 212
A12: 45112 | B12: ABDUL KARIM | D12: 144 | E12: =E11-D12+C12 -> 68
A13: 45120 | B13: SERADJO COSMATIQUE | D13: 68 | E13: =E12-D13+C13 -> 0
E14: =E13-D14+C14 -> 0
E15: =E14-D15+C15 -> 0
E16: =E15-D16+C16 -> 0
E17: =E16/144 -> 0

Sheet KOJIC WHITE 4 IN 1 SOAP 160GM
A1: KOJIC WHITE 4 IN 1 SOAP 160GM
A2: DATE | B2: PARTICULARS | C2: IN | D2: OUT | E2: BALANCE
A3: 44881 | B3: KOJIC WHITE 4 IN 1 SOAP 160GM | C3: 144 | E3: =C3 -> 144
A4: 44881 | B4: MAMOUDOU YAYA LABE | D4: 30 | E4: =E3-D4+C4 -> 114
A5: 44690 | B5: SYLLA COSMATIQUE | D5: 114 | E5: =E4-D5+C5 -> 0
E6: =E5-D6+C6 -> 0
E7: =E6-D7+C7 -> 0
E8: =E7-D8+C8 -> 0
E9: =E8-D9+C9 -> 0
E10: =E9-D10+C10 -> 0
E11: =E10-D11+C11 -> 0
E12: =E11-D12+C12 -> 0
E13: =E12-D13+C13 -> 0
E14: =E13/144 -> 0

Sheet PAPAYA HONEY LEMON SOAP 160GM
A1: KOJIC WHITE 4 IN 1 PAPAYA HONEY LEMON SOAP 160GM
A2: DATE | B2: PARTICULARS | C2: IN | D2: OUT | E2: BALANCE
E3: 48
A4: 45030 | B4: CASH SALE | D4: 48 | E4: =E3-D4+C4 -> 0
E5: =E4-D5+C5 -> 0
E6: =E5-D6+C6 -> 0
E7: =E6-D7+C7 -> 0
E8: =E7-D8+C8 -> 0
E9: =E8-D9+C9 -> 0
E10: =E9-D10+C10 -> 0
E11: =E10-D11+C11 -> 0
E12: =E11-D12+C12 -> 0
E13: =E12/144 -> 0

Sheet GLUTA CLEAR & GLUTA SOAP 160GM
A1: MADAM WHITE STEM CELL GLUTA CLEAR & GLUTA SOAP 160GM
A2: DATE | B2: PARTICULARS | C2: IN | D2: OUT | E2: BALANCE
E3: 96
A4: 45030 | B4: CASH SALE | D4: 96 | E4: =E3-D4+C4 -> 0
A5: 45072 | B5: RECED FROM WAREHOSUE | C5: 288 | E5: =E4-D5+C5 -> 288
A6: 45098 | B6: SULEMAN COSMATIQUE | D6: 288 | E6: =E5-D6+C6 -> 0
E7: =E6-D7+C7 -> 0
E8: =E7-D8+C8 -> 0
E9: =E8-D9+C9 -> 0
E10: =E9-D10+C10 -> 0
E11: =E10-D11+C11 -> 0
E12: =E11-D12+C12 -> 0
E13: =E12/144 -> 0

Sheet CALLAGEN & GLUTA SOAP 160GM
A1: MADAM WHITE TOMATO CALLAGEN & GLUTA SOAP 160GM
A2: DATE | B2: PARTICULARS | C2: IN | D2: OUT | E2: BALANCE
E3: 90
A4: 45031 | B4: MAMDOU SALIOU | D4: 90 | E4: =E3-D4+C4 -> 0
E5: =E4-D5+C5 -> 0
E6: =E5-D6+C6 -> 0
E7: =E6-D7+C7 -> 0
E8: =E7-D8+C8 -> 0
E9: =E8-D9+C9 -> 0
E10: =E9-D10+C10 -> 0
E11: =E10-D11+C11 -> 0
E12: =E11-D12+C12 -> 0
E13: =E12/144 -> 0

Sheet Gluta Tomato Carrot Soap 135gm
A1: Koijc C Extract Gluta Tomato Carrot Soap 135gm
A2: DATE | B2: PARTICULARS | C2: IN | D2: OUT | E2: BALANCE
E3: 72
A4: 44912 | B4: FREETOWN BRANCH | D4: 72 | E4: =E3-D4+C4 -> 0
E5: =E4-D5+C5 -> 0
E6: =E5-D6+C6 -> 0
E7: =E6-D7+C7 -> 0
E8: =E7-D8+C8 -> 0
E9: =E8-D9+C9 -> 0
E10: =E9-D10+C10 -> 0
E11: =E10-D11+C11 -> 0
E12: =E11-D12+C12 -> 0
E13: =E12-D13+C13 -> 0
E14: =E13/72 -> 0

Sheet KOJIC C EXTRACT GLUTA SOAP135GM
A1: KOJIC C EXTRACT GLUTA PAPAYA SOAP 135GM
A2: DATE | B2: PARTICULARS | C2: IN | D2: OUT | E2: BALANCE
E3: 66
A4: 45031 | B4: MAMDOU SALIOU | D4: 54 | E4: =E3-D4+C4 -> 12
A5: 45036 | B5: SACKO PROMOTION | D5: 12 | E5: =E4-D5+C5 -> 0
E6: =E5-D6+C6 -> 0
E7: =E6-D7+C7 -> 0
E8: =E7-D8+C8 -> 0
E9: =E8-D9+C9 -> 0
E10: =E9-D10+C10 -> 0
E11: =E10-D11+C11 -> 0
E12: =E11-D12+C12 -> 0
E13: =E12/72 -> 0

Sheet AX1 Kojic Papaya  Soap 135gm 
A1: AX1 Kojic Papaya Soap 135gm
A2: DATE | B2: PARTICULARS | C2: IN | D2: OUT | E2: BALANCE
A3: 44894 | B3: RECDD FROM WAREHOUSE | C3: =144*2 -> 288 | E3: =C3 -> 288
A4: 44894 | B4: CASH SALE | D4: 144 | E4: =E3-D4+C4 -> 144
A5: 45051 | B5: ISMAIL COSMATIQUE | D5: 144 | E5: =E4-D5+C5 -> 0
E6: =E5-D6+C6 -> 0
E7: =E6-D7+C7 -> 0
E8: =E7-D8+C8 -> 0
E9: =E8-D9+C9 -> 0
E10: =E9-D10+C10 -> 0
E11: =E10-D11+C11 -> 0
E12: =E11-D12+C12 -> 0
E13: =E12-D13+C13 -> 0
E14: =E13/144 -> 0

Sheet KOJIC GALLAGEN GLUTA SOAP 135GM
A1: AX1 KOJIC GALLAGEN GLUTA SOAP 135 GM
A2: DATE | B2: PARTICULARS | C2: IN | D2: OUT | E2: BALANCE
E3: 102
A4: 45036 | B4: SACKO PROMOTION | D4: 92 | E4: =E3-D4+C4 -> 10
A5: 44690 | B5: SYLLA COSMATIQUE | D5: 10 | E5: =E4-D5+C5 -> 0
E6: =E5-D6+C6 -> 0
E7: =E6-D7+C7 -> 0
E8: =E7-D8+C8 -> 0
E9: =E8-D9+C9 -> 0
E10: =E9-D10+C10 -> 0
E11: =E10-D11+C11 -> 0
E12: =E11-D12+C12 -> 0
E13: =E12/144 -> 0

Sheet KOJIC GLUTA PLUS SOAP 135GM
A1: NANO KOJIC GLUTA PLUS SOAP 135GM
A2: DATE | B2: PARTICULARS | C2: IN | D2: OUT | E2: BALANCE
A3: 44881 | B3: NANO KOJIC GLUTA PLUS SOAP 135GM | C3: 144 | E3: =C3 -> 144
A4: 44881 | B4: MAMOUDOU YAYA LABE | D4: 36 | E4: =E3-D4+C4 -> 108
A5: 44690 | B5: SYLLA COSMATIQUE | D5: 56 | E5: =E4-D5+C5 -> 52
A6: 44696 | B6: THIERNO BARRY COSMATIQUE | D6: 52 | E6: =E5-D6+C6 -> 0
A7: 44707 | B7: RECED FROM WAREHOUSE | C7: 432 | E7: =E6-D7+C7 -> 432
A8: 44748 | B8: SADIO COSMATIQUE | D8: 84 | E8: =E7-D8+C8 -> 348
